Workbook

Sheet Calc
L1: Row | M1: 46 | N1: 67 | P1: 81 | Q1: 104 | S1: 115 | T1: 142 | W1: 169
B2: Lansdowne | M2: Based on SQM | P2: Based on Asset Value (Fixed Based on Weighted Age/Asset/risk) | S2: Based on % minutes worked | V2: Based on % Staff | Z2: Total | AD2: Total Per Minute | BB2: Ave Increase
A3: Date:2017/10/17 10:28 | C3: Asset Value | D3: SQM | M3: Fixed | N3: Variable | P3: Fixed | Q3: Variable | S3: Fixed | T3: Variable | V3: Fixed | W3: Variable | Y3: Wages | Z3: Fixed | AA3: Variable | AC3: Wages | AD3: Fixed | AE3: Variable | AF3: Current | AH3: % Change | AJ3: Syspro | AK3: 46054 | AL3: 45870 | AM3: 45689 | AN3: 45323 | AO3: 45199 | AP3: 44958 | AQ3: 44927 | AR3: 44804 | AS3: 44620 | AT3: 44440 | AU3: 44248 | AV3: 43862 | AW3: 43497 | AX3: 43132 | AY3: 42767 | AZ3: 42401 | BB3: =AVERAGE(BB5:BB116) -> #DIV/0!
A4: Work center | B4: Description | F4: Qty | G4: Sum | I4: Old Cost per Min | J4: Labour Price per Man Minute | L4: Minutes worked per year | M4: =HLOOKUP($B$14,Overhead!$E:$E,M$1,FALSE) -> 301413.49 | N4: =HLOOKUP($B$14,Overhead!$E:$E,N$1,FALSE) -> 19679.793 | P4: =HLOOKUP($B$14,Overhead!$E:$E,P$1,FALSE) -> 151950.61 | Q4: =HLOOKUP($B$14,Overhead!$E:$E,Q$1,FALSE) -> 177767.45 | S4: =HLOOKUP($B$14,Overhead!$E:$E,S$1,FALSE) -> 691435.62 | T4: =HLOOKUP($B$14,Overhead!$E:$E,T$1,FALSE) -> 256024.4 | W4: =HLOOKUP($B$14,Overhead!$E:$E,W$1,FALSE) -> 75138.443 | Y4: =SUM(Y5:Y13) -> 3601081.3 | Z4: =+M4+P4+S4+V4 -> 1144799.7 | AA4: =+N4+Q4+T4+W4 -> 528610.09
A5: M00001 | B5: Bending Brakes and PS00005 | C5: =SUMIF('Asset Allocation'!$F$1:$I$270,Calc!A5,'Asset Allocation'!I:I) -> 2342981.9 | D5: 77 | E5: M00001 | F5: =SUMIF(Wages!$O$2:$P$220,Calc!E5,Wages!$P$2:$P$220) -> 2.55 | G5: =SUMIF(Wages!$O$2:$AD$192,Calc!E5,Wages!$AD$2:$AD$192) -> 1197334.5 | I5: 2.02 | J5: =+G5/L5 -> 4.0758935 | L5: =+F5*40*48*60 -> 293760 | M5: =+D5/$D$14*M$4 -> 69696.211 | N5: =+D5/$D$14*N$4 -> 4550.5827 | P5: =+C5/$C$14*$P$4 -> 113851.01 | Q5: =+$Q$4*C5/$C$14 -> 133194.62 | S5: =+L5/$L$14*$S$4 -> 192695.17 | T5: =+L5/$L$14*$T$4 -> 71351.064 | W5: =+F5/$F$14*$W$4 -> 20940.222 | Y5: =+G5 -> 1197334.5 | Z5: =+M5+P5+S5+V5 -> 376242.39 | AA5: =+N5+Q5+T5+W5 -> 230036.49 | AC5: =+Y5/L5 -> 4.0758935 | AD5: =+Z5/$L5 -> 1.2807816 | AE5: =+AA5/$L5 -> 0.78307628 | AF5: =SUM(AC5:AE5) -> 6.1397513 | AG5: x | AH5: =+(AF5-AJ5)/AJ5 -> -4.0497278e-05 | AJ5: =VLOOKUP(E5,Syspro!$A$2:$F$91,6,FALSE) -> 6.14 | AK5: 7.52 | AL5: 7.0896489 | AM5: 6.56 | AN5: 4.53 | AO5: 4.02 | AP5: 4.0202097 | AQ5: 3.93 | AR5: 3.75 | AS5: 3.75 | AT5: 3.96 | AU5: 3.88 | AV5: 4.45 | AW5: 4.0724898 | AX5: 3.7362698 | AY5: 3.49 | AZ5: 3.03 | BB5: =(+AF5-AJ5)/AJ5 -> -4.0497278e-05
A6: M00002 | B6: Spot Welding and PS00006 | C6: =SUMIF('Asset Allocation'!$F$1:$I$270,Calc!A6,'Asset Allocation'!I:I) -> 207705.78 | D6: 22 | E6: M00002 | F6: =SUMIF(Wages!$O$2:$P$220,Calc!E6,Wages!$P$2:$P$220) -> 1.3 | G6: =SUMIF(Wages!$O$2:$AD$192,Calc!E6,Wages!$AD$2:$AD$192) -> 469995.19 | I6: 2.02 | J6: =+G6/L6 -> 3.1383226 | L6: =+F6*40*48*60 -> 149760 | M6: =+D6/$D$14*M$4 -> 19913.203 | N6: =+D6/$D$14*N$4 -> 1300.1665 | P6: =+C6/$C$14*$P$4 -> 10092.913 | Q6: =+$Q$4*C6/$C$14 -> 11807.728 | S6: =+L6/$L$14*$S$4 -> 98236.754 | T6: =+L6/$L$14*$T$4 -> 36375.052 | W6: =+F6/$F$14*$W$4 -> 10675.407 | Y6: =+G6 -> 469995.19 | Z6: =+M6+P6+S6+V6 -> 128242.87 | AA6: =+N6+Q6+T6+W6 -> 60158.354 | AC6: =+Y6/L6 -> 3.1383226 | AD6: =+Z6/$L6 -> 0.85632259 | AE6: =+AA6/$L6 -> 0.40169841 | AF6: =SUM(AC6:AE6) -> 4.3963435 | AG6: x | AH6: =+(AF6-AJ6)/AJ6 -> -0.00083101205 | AJ6: =VLOOKUP(E6,Syspro!$A$2:$F$91,6,FALSE) -> 4.4 | AK6: 4.42 | AL6: 3.9685487 | AM6: 4.15 | AN6: 4.37 | AO6: 4.07 | AP6: 4.0710459 | AQ6: 3.9 | AR6: 3.73 | AS6: 3.73 | AT6: 3.47 | AU6: 3.44 | AV6: 4.59 | AW6: 4.0315629 | AX6: 3.4428349 | AY6: 3.49 | AZ6: 3.03 | BB6: =(+AF6-AJ6)/AJ6 -> -0.00083101205
A7: M00003 | B7: Grinding Stations and PS00007 | C7: =SUMIF('Asset Allocation'!$F$1:$I$270,Calc!A7,'Asset Allocation'!I:I) -> 53256 | D7: 53 | E7: M00003 | F7: =SUMIF(Wages!$O$2:$P$220,Calc!E7,Wages!$P$2:$P$220) -> 0.25 | G7: =SUMIF(Wages!$O$2:$AD$192,Calc!E7,Wages!$AD$2:$AD$192) -> 80042.533 | I7: 2.02 | J7: =+G7/L7 -> 2.7792546 | L7: =+F7*40*48*60 -> 28800 | M7: =+D7/$D$14*M$4 -> 47972.717 | N7: =+D7/$D$14*N$4 -> 3132.2193 | P7: =+C7/$C$14*$P$4 -> 2587.8345 | Q7: =+$Q$4*C7/$C$14 -> 3027.5149 | S7: =+L7/$L$14*$S$4 -> 18891.684 | T7: =+L7/$L$14*$T$4 -> 6995.2023 | W7: =+F7/$F$14*$W$4 -> 2052.9629 | Y7: =+G7 -> 80042.533 | Z7: =+M7+P7+S7+V7 -> 69452.235 | AA7: =+N7+Q7+T7+W7 -> 15207.899 | AC7: =+Y7/L7 -> 2.7792546 | AD7: =+Z7/$L7 -> 2.4115359 | AE7: =+AA7/$L7 -> 0.52805206 | AF7: =SUM(AC7:AE7) -> 5.7188426 | AG7: x | AH7: =+(AF7-AJ7)/AJ7 -> -0.00020234211 | AJ7: =VLOOKUP(E7,Syspro!$A$2:$F$91,6,FALSE) -> 5.72 | AK7: 5.71 | AL7: 5.3915324 | AM7: 5.34 | AN7: 4.06 | AO7: 2.96 | AP7: 2.9592541 | AQ7: 3.82 | AR7: 3.63 | AS7: 3.63 | AT7: 4.76 | AU7: 4.03 | AV7: 4.14 | AW7: 4.1095591 | AX7: 3.7789618 | AY7: 3.49 | AZ7: 3.03 | BB7: =(+AF7-AJ7)/AJ7 -> -0.00020234211
A8: M00004 | B8: Notching an PS00008 | C8: =SUMIF('Asset Allocation'!$F$1:$I$270,Calc!A8,'Asset Allocation'!I:I) -> 12700 | D8: 4 | E8: M00004 | F8: =SUMIF(Wages!$O$2:$P$220,Calc!E8,Wages!$P$2:$P$220) -> 0.25 | G8: =SUMIF(Wages!$O$2:$AD$192,Calc!E8,Wages!$AD$2:$AD$192) -> 80042.533 | I8: 2.02 | J8: =+G8/L8 -> 2.7792546 | L8: =+F8*40*48*60 -> 28800 | M8: =+D8/$D$14*M$4 -> 3620.5824 | N8: =+D8/$D$14*N$4 -> 236.39391 | P8: =+C8/$C$14*$P$4 -> 617.12292 | Q8: =+$Q$4*C8/$C$14 -> 721.97386 | S8: =+L8/$L$14*$S$4 -> 18891.684 | T8: =+L8/$L$14*$T$4 -> 6995.2023 | W8: =+F8/$F$14*$W$4 -> 2052.9629 | Y8: =+G8 -> 80042.533 | Z8: =+M8+P8+S8+V8 -> 23129.389 | AA8: =+N8+Q8+T8+W8 -> 10006.533 | AC8: =+Y8/L8 -> 2.7792546 | AD8: =+Z8/$L8 -> 0.80310378 | AE8: =+AA8/$L8 -> 0.34744906 | AF8: =SUM(AC8:AE8) -> 3.9298074 | AG8: x | AH8: =+(AF8-AJ8)/AJ8 -> -4.899607e-05 | AJ8: =VLOOKUP(E8,Syspro!$A$2:$F$91,6,FALSE) -> 3.93 | AK8: 3.94 | AL8: 3.690239 | AM8: 3.63 | AN8: 4.09 | AO8: 3.89 | AP8: 3.8938812 | AQ8: 3.8 | AR8: 3.58 | AS8: 3.58 | AT8: 3.63 | AU8: 3.55 | AV8: 5.12 | AW8: 4.7102179 | AX8: 4.1179881 | AY8: 3.49 | AZ8: 3.03 | BB8: =(+AF8-AJ8)/AJ8 -> -4.899607e-05
A9: M00014 | B9: Guilotene | C9: =SUMIF('Asset Allocation'!$F$1:$I$270,Calc!A9,'Asset Allocation'!I:I) -> 262767.15 | D9: 89 | E9: M00014 | F9: =SUMIF(Wages!$O$2:$P$220,Calc!E9,Wages!$P$2:$P$220) -> 1 | G9: =SUMIF(Wages!$O$2:$AD$192,Calc!E9,Wages!$AD$2:$AD$192) -> 458354.62 | I9: 2.02 | J9: =+G9/L9 -> 3.9787727 | L9: =+F9*40*48*60 -> 115200 | M9: =+D9/$D$14*M$4 -> 80557.959 | N9: =+D9/$D$14*N$4 -> 5259.7644 | P9: =+C9/$C$14*$P$4 -> 12768.475 | Q9: =+$Q$4*C9/$C$14 -> 14937.875 | S9: =+L9/$L$14*$S$4 -> 75566.734 | T9: =+L9/$L$14*$T$4 -> 27980.809 | W9: =+F9/$F$14*$W$4 -> 8211.8517 | Y9: =+G9 -> 458354.62 | Z9: =+M9+P9+S9+V9 -> 168893.17 | AA9: =+N9+Q9+T9+W9 -> 56390.3 | AC9: =+Y9/L9 -> 3.9787727 | AD9: =+Z9/$L9 -> 1.4660865 | AE9: =+AA9/$L9 -> 0.48949914 | AF9: =SUM(AC9:AE9) -> 5.9343584 | AG9: x | AH9: =+(AF9-AJ9)/AJ9 -> -0.00094976421 | AJ9: =VLOOKUP(E9,Syspro!$A$2:$F$91,6,FALSE) -> 5.94 | AK9: 5.96 | AL9: 5.6500617 | AM9: 5.5 | AN9: 4.44 | AO9: 4.24 | AP9: 4.244345 | AQ9: 3.97 | AR9: 3.53 | AS9: 3.53 | AT9: 4 | AU9: 3.92 | AV9: 4.79 | AW9: 4.7974945 | AX9: 4.5467463 | AY9: 3.49 | AZ9: 3.03 | BB9: =(+AF9-AJ9)/AJ9 -> -0.00094976421
A10: M00006 | B10: Rolling and PS00009 | C10: =SUMIF('Asset Allocation'!$F$1:$I$270,Calc!A10,'Asset Allocation'!I:I) -> 59200 | D10: 14 | E10: M00006 | F10: =SUMIF(Wages!$O$2:$P$220,Calc!E10,Wages!$P$2:$P$220) -> 1.35 | G10: =SUMIF(Wages!$O$2:$AD$192,Calc!E10,Wages!$AD$2:$AD$192) -> 355699.45 | I10: 2.02 | J10: =+G10/L10 -> 2.2871621 | L10: =+F10*40*48*60 -> 155520 | M10: =+D10/$D$14*M$4 -> 12672.038 | N10: =+D10/$D$14*N$4 -> 827.37868 | P10: =+C10/$C$14*$P$4 -> 2876.6675 | Q10: =+$Q$4*C10/$C$14 -> 3365.4215 | S10: =+L10/$L$14*$S$4 -> 102015.09 | T10: =+L10/$L$14*$T$4 -> 37774.092 | W10: =+F10/$F$14*$W$4 -> 11086 | Y10: =+G10 -> 355699.45 | Z10: =+M10+P10+S10+V10 -> 117563.8 | AA10: =+N10+Q10+T10+W10 -> 53052.892 | AC10: =+Y10/L10 -> 2.2871621 | AD10: =+Z10/$L10 -> 0.75594005 | AE10: =+AA10/$L10 -> 0.34113228 | AF10: =SUM(AC10:AE10) -> 3.3842344 | AG10: x | AH10: =+(AF10-AJ10)/AJ10 -> -0.0017007537 | AJ10: =VLOOKUP(E10,Syspro!$A$2:$F$91,6,FALSE) -> 3.39 | AK10: 3.5 | AL10: 3.1886977 | AM10: 3.25 | AN10: 4.1 | AO10: 3.76 | AP10: 3.7548395 | AQ10: 3.67 | AR10: 3.5 | AS10: 3.5 | AT10: 3.43 | AU10: 3.38 | AV10: 4.84 | AW10: 4.2076158 | AX10: 3.5750546 | AY10: 3.49 | AZ10: 3.03 | BB10: =(+AF10-AJ10)/AJ10 -> -0.0017007537
A11: M00007 | B11: Beading | C11: =SUMIF('Asset Allocation'!$F$1:$I$270,Calc!A11,'Asset Allocation'!I:I) -> 44000 | D11: 14 | E11: M00007 | F11: =SUMIF(Wages!$O$2:$P$220,Calc!E11,Wages!$P$2:$P$220) -> 0.1 | G11: =SUMIF(Wages!$O$2:$AD$192,Calc!E11,Wages!$AD$2:$AD$192) -> 46939.849 | I11: 2.02 | J11: =+G11/L11 -> 4.0746397 | L11: =+F11*40*48*60 -> 11520 | M11: =+D11/$D$14*M$4 -> 12672.038 | N11: =+D11/$D$14*N$4 -> 827.37868 | P11: =+C11/$C$14*$P$4 -> 2138.0637 | Q11: =+$Q$4*C11/$C$14 -> 2501.3268 | S11: =+L11/$L$14*$S$4 -> 7556.6734 | T11: =+L11/$L$14*$T$4 -> 2798.0809 | W11: =+F11/$F$14*$W$4 -> 821.18517 | Y11: =+G11 -> 46939.849 | Z11: =+M11+P11+S11+V11 -> 22366.776 | AA11: =+N11+Q11+T11+W11 -> 6947.9715 | AC11: =+Y11/L11 -> 4.0746397 | AD11: =+Z11/$L11 -> 1.9415604 | AE11: =+AA11/$L11 -> 0.60312253 | AF11: =SUM(AC11:AE11) -> 6.6193226 | AG11: x | AH11: =+(AF11-AJ11)/AJ11 -> 0.0014103721 | AJ11: =VLOOKUP(E11,Syspro!$A$2:$F$91,6,FALSE) -> 6.61 | AK11: 6.64 | AL11: 6.3095377 | AM11: 6.18 | AN11: 4.2 | AO11: 3.78 | AP11: 3.7810959 | AQ11: 3.71 | AR11: 3.51 | AS11: 3.51 | AT11: 3.44 | AU11: 3.4 | AV11: 4.41 | AW11: 3.9064988 | AX11: 3.3334163 | AY11: 3.49 | AZ11: 3.03 | BB11: =(+AF11-AJ11)/AJ11 -> 0.0014103721
A12: M00099 | B12: Miscellaneous and PS00011 | C12: =SUMIF('Asset Allocation'!$F$1:$I$270,Calc!A12,'Asset Allocation'!I:I) -> 129490.78 | D12: 20 | E12: M00099 | F12: =SUMIF(Wages!$O$2:$P$220,Calc!E12,Wages!$P$2:$P$220) -> 1.25 | G12: =SUMIF(Wages!$O$2:$AD$192,Calc!E12,Wages!$AD$2:$AD$192) -> 416130.56 | I12: 2.02 | J12: =+G12/L12 -> 2.8897955 | L12: =+F12*40*48*60 -> 144000 | M12: =+D12/$D$14*M$4 -> 18102.912 | N12: =+D12/$D$14*N$4 -> 1181.9695 | P12: =+C12/$C$14*$P$4 -> 6292.2621 | Q12: =+$Q$4*C12/$C$14 -> 7361.3353 | S12: =+L12/$L$14*$S$4 -> 94458.418 | T12: =+L12/$L$14*$T$4 -> 34976.012 | W12: =+F12/$F$14*$W$4 -> 10264.815 | Y12: =+G12 -> 416130.56 | Z12: =+M12+P12+S12+V12 -> 118853.59 | AA12: =+N12+Q12+T12+W12 -> 53784.131 | AC12: =+Y12/L12 -> 2.8897955 | AD12: =+Z12/$L12 -> 0.82537217 | AE12: =+AA12/$L12 -> 0.37350091 | AF12: =SUM(AC12:AE12) -> 4.0886686 | AG12: x | AH12: =+(AF12-AJ12)/AJ12 -> -0.00032552493 | AJ12: =VLOOKUP(E12,Syspro!$A$2:$F$91,6,FALSE) -> 4.09 | AK12: 4.2 | AL12: 3.7800581 | AM12: 4.05 | AN12: 4.43 | AO12: 4.07 | AP12: 4.0691209 | AQ12: 3.97 | AR12: 3.56 | AS12: 3.56 | AT12: 3.51 | AU12: 3.46 | AV12: 3.41 | AW12: 4.0426559 | AX12: 3.5426329 | AY12: 3.49 | AZ12: 3.03 | BB12: =(+AF12-AJ12)/AJ12 -> -0.00032552493
A13: M00008 | B13: Mig Welding and PS00010 | C13: =SUMIF('Asset Allocation'!$F$1:$I$270,Calc!A13,'Asset Allocation'!I:I) -> 14946 | D13: 40 | E13: M00008 | F13: =SUMIF(Wages!$O$2:$P$220,Calc!E13,Wages!$P$2:$P$220) -> 1.1 | G13: =SUMIF(Wages!$O$2:$AD$192,Calc!E13,Wages!$AD$2:$AD$192) -> 496542.06 | I13: 2.02 | J13: =+G13/L13 -> 3.918419 | L13: =+F13*40*48*60 -> 126720 | M13: =+D13/$D$14*M$4 -> 36205.824 | N13: =+D13/$D$14*N$4 -> 2363.9391 | P13: =+C13/$C$14*$P$4 -> 726.26135 | Q13: =+$Q$4*C13/$C$14 -> 849.65522 | S13: =+L13/$L$14*$S$4 -> 83123.408 | T13: =+L13/$L$14*$T$4 -> 30778.89 | W13: =+F13/$F$14*$W$4 -> 9033.0369 | Y13: =+G13 -> 496542.06 | Z13: =+M13+P13+S13+V13 -> 120055.49 | AA13: =+N13+Q13+T13+W13 -> 43025.521 | AC13: =+Y13/L13 -> 3.918419 | AD13: =+Z13/$L13 -> 0.94740762 | AE13: =+AA13/$L13 -> 0.33953221 | AF13: =SUM(AC13:AE13) -> 5.2053589 | AG13: x | AH13: =+(AF13-AJ13)/AJ13 -> -0.00089081561 | AJ13: =VLOOKUP(E13,Syspro!$A$2:$F$91,6,FALSE) -> 5.21 | AK13: 5.21 | AL13: 4.9506932 | AM13: 4.84 | AN13: 4.34 | AO13: 4.15 | AP13: 4.1522814 | AQ13: 4.04 | AR13: 3.52 | AS13: 3.52 | AT13: 3.83 | AU13: 3.57 | AV13: 4.42 | AW13: 4.0331648 | AX13: 3.6805127 | AY13: 3.49 | AZ13: 3.03 | BB13: =(+AF13-AJ13)/AJ13 -> -0.00089081561
B14: Manufacturing | C14: =SUM(C5:C13) -> 3127047.6 | D14: =SUM(D5:D13) -> 333 | F14: =SUM(F5:F13) -> 9.15 | L14: =+SUM(L5:L13) -> 1054080 | AB14: x
B16: Ottery
A17: M00009 | B17: Bending Breaks Ottery | C17: =SUMIF('Asset Allocation'!$F$1:$I$270,Calc!A17,'Asset Allocation'!I:I) -> 0 | D17: 0 | E17: M00009 | F17: =SUMIF(Wages!$O$2:$P$190,Calc!E17,Wages!$P$2:$P$190) -> 0 | G17: =SUMIF(Wages!$O$2:$AD$192,Calc!E17,Wages!$AD$2:$AD$192) -> 0 | AJ17: 0 | AK17: 0 | AM17: 0 | AN17: 0 | AO17: 0 | AQ17: 0 | AR17: 0 | AS17: 0 | AT17: 0 | AU17: 0 | AV17: 4.38 | AW17: 3.9662936 | AX17: 3.6341206 | AY17: 3.49 | AZ17: 3.03 | BB17: =(+AF17-AW17)/AW17 -> -1
A18: M00010 | B18: Spot Welding Ottery | C18: =SUMIF('Asset Allocation'!$F$1:$I$270,Calc!A18,'Asset Allocation'!I:I) -> 0 | D18: 0 | E18: M00010 | F18: =SUMIF(Wages!$O$2:$P$190,Calc!E18,Wages!$P$2:$P$190) -> 0 | G18: =SUMIF(Wages!$O$2:$AD$192,Calc!E18,Wages!$AD$2:$AD$192) -> 0 | AJ18: 0 | AK18: 0 | AM18: 0 | AN18: 0 | AO18: 0 | AQ18: 0 | AR18: 0 | AS18: 0 | AT18: 0 | AU18: 0 | AV18: 3.88 | AW18: 4.2850296 | AX18: 3.8044197 | AY18: 3.49 | AZ18: 3.03 | BB18: =(+AF18-AW18)/AW18 -> -1
A19: M00011 | B19: Rolling Ottery | C19: =SUMIF('Asset Allocation'!$F$1:$I$270,Calc!A19,'Asset Allocation'!I:I) -> 0 | D19: 0 | E19: M00011 | F19: =SUMIF(Wages!$O$2:$P$190,Calc!E19,Wages!$P$2:$P$190) -> 0 | G19: =SUMIF(Wages!$O$2:$AD$192,Calc!E19,Wages!$AD$2:$AD$192) -> 0 | AJ19: 0 | AK19: 0 | AM19: 0 | AN19: 0 | AO19: 0 | AQ19: 0 | AR19: 0 | AS19: 0 | AT19: 0 | AU19: 0 | AV19: 3.47 | AW19: 3.5357021 | AX19: 3.1478332 | AY19: 3.49 | AZ19: 3.03 | BB19: =(+AF19-AW19)/AW19 -> -1
A20: M00012 | B20: Beading Ottery | C20: =SUMIF('Asset Allocation'!$F$1:$I$270,Calc!A20,'Asset Allocation'!I:I) -> 0 | D20: 0 | E20: M00012 | F20: =SUMIF(Wages!$O$2:$P$190,Calc!E20,Wages!$P$2:$P$190) -> 0 | G20: =SUMIF(Wages!$O$2:$AD$192,Calc!E20,Wages!$AD$2:$AD$192) -> 0 | AJ20: 0 | AK20: 0 | AM20: 0 | AN20: 0 | AO20: 0 | AQ20: 0 | AR20: 0 | AS20: 0 | AT20: 0 | AU20: 0 | AV20: 3.76 | AW20: 4.2782884 | AX20: 3.7822454 | AY20: 3.49 | AZ20: 3.03 | BB20: =(+AF20-AW20)/AW20 -> -1
A21: M00013 | B21: Mig Welding Ottery | C21: =SUMIF('Asset Allocation'!$F$1:$I$270,Calc!A21,'Asset Allocation'!I:I) -> 0 | D21: 0 | E21: M00013 | F21: =SUMIF(Wages!$O$2:$P$190,Calc!E21,Wages!$P$2:$P$190) -> 0 | G21: =SUMIF(Wages!$O$2:$AD$192,Calc!E21,Wages!$AD$2:$AD$192) -> 0 | AJ21: 0 | AK21: 0 | AM21: 0 | AN21: 0 | AO21: 0 | AQ21: 0 | AR21: 0 | AS21: 0 | AT21: 0 | AU21: 0 | AV21: 4.13 | AW21: 4.0239837 | AX21: 3.7565265 | AY21: 3.49 | AZ21: 3.03 | BB21: =(+AF21-AW21)/AW21 -> -1
A22: M00005 | B22: Guilotene | C22: =SUMIF('Asset Allocation'!$F$1:$I$270,Calc!A22,'Asset Allocation'!I:I) -> 0 | D22: 0 | E22: M00005 | F22: =SUMIF(Wages!$O$2:$P$190,Calc!E22,Wages!$P$2:$P$190) -> 0 | G22: =SUMIF(Wages!$O$2:$AD$192,Calc!E22,Wages!$AD$2:$AD$192) -> 0 | AJ22: 0 | AK22: 0 | AM22: 0 | AN22: 0 | AO22: 0 | AQ22: 0 | AR22: 0 | AS22: 0 | AT22: 0 | AU22: 0 | AV22: 5.73 | AW22: 5.4924862 | AX22: 5.1733211 | AY22: 3.49 | AZ22: 3.03 | BB22: =(+AF22-AW22)/AW22 -> -1
B23: Total SQM | C23: =SUM(C16:C22) -> 0 | D23: 0 | F23: =SUM(F17:F22) -> 0
A24: Trumpf | E24: Trumpf | M24: =HLOOKUP($B$26,Overhead!$G:$G,M$1,FALSE) -> 108125.48 | N24: =HLOOKUP($B$26,Overhead!$G:$G,N$1,FALSE) -> 7059.7352 | P24: =HLOOKUP($B$26,Overhead!$G:$G,P$1,FALSE) -> 314754.83 | Q24: =HLOOKUP($B$26,Overhead!$G:$G,Q$1,FALSE) -> 245430.24 | S24: =HLOOKUP($B$26,Overhead!$G:$G,S$1,FALSE) -> 518364.25 | T24: =HLOOKUP($B$26,Overhead!$G:$G,T$1,FALSE) -> 188524.1 | W24: =HLOOKUP($B$26,Overhead!$G:$G,W$1,FALSE) -> 8211.8517 | Y24: =+Y25 -> 412182.08 | Z24: =+Z25 -> 941244.56 | AA24: =+AA25 -> 449225.92
A25: 05 | B25: Trumpf | C25: =SUMIF('Asset Allocation'!$F$1:$I$270,Calc!A25,'Asset Allocation'!I:I) -> 4317281 | D25: 111 | E25: 05 | F25: 1 | G25: =SUMIF(Wages!$O$2:$AD$192,Calc!E25,Wages!$AD$2:$AD$192) -> 412182.08 | I25: 4.07 | J25: =+G25/L25 -> 3.5779695 | L25: =40*48*60 -> 115200 | M25: =+$D$25/$D$26*M$24 -> 108125.48 | N25: =+$D$25/$D$26*N$24 -> 7059.7352 | P25: =+$D$25/$D$26*P$24 -> 314754.83 | Q25: =+$D$25/$D$26*Q$24 -> 245430.24 | S25: =+$L$25/$L$26*$S$24 -> 518364.25 | T25: =+$L$25/$L$26*$T$24 -> 188524.1 | W25: =+$F$25/$F$26*W$24 -> 8211.8517 | Y25: =+G25 -> 412182.08 | Z25: =+M25+P25+S25+V25 -> 941244.56 | AA25: =+N25+Q25+T25+W25 -> 449225.92 | AB25: x | AC25: =+Y25/L25 -> 3.5779695 | AD25: =+Z25/$L25 -> 8.1705257 | AE25: =+AA25/$L25 -> 3.8995306 | AF25: =SUM(AC25:AE25) -> 15.648026 | AH25: =+(AF25-AJ25)/AJ25 -> -0.00012614959 | AJ25: =VLOOKUP(E25,Syspro!$A$2:$F$91,6,FALSE) -> 15.65 | AK25: 15.85 | AL25: 14.459058 | AM25: 14.39 | AN25: 12.77 | AO25: 12.61 | AP25: 12.608115 | AQ25: 11.8 | AR25: 13.33 | AS25: 13.33 | AT25: 14.61 | AU25: 14.22 | AV25: 16.83 | AW25: 15.850981 | AX25: 16.596263 | AY25: 19.5 | AZ25: 14.56 | BB25: =(+AF25-AJ25)/AJ25 -> -0.00012614959
B26: Trumpf | C26: =+C25 -> 4317281 | D26: =SUM(D25) -> 111 | F26: =SUM(F25) -> 1 | L26: =SUM(L25) -> 115200
A27: Assembly | B27: Lansdowne | E27: Assembly | M27: =HLOOKUP($B$34,Overhead!$H:$H,M$1,FALSE) -> 551155.83 | N27: =HLOOKUP($B$34,Overhead!$H:$H,N$1,FALSE) -> 35985.907 | P27: =HLOOKUP($B$34,Overhead!$H:$H,P$1,FALSE) -> 10853.615 | Q27: =HLOOKUP($B$34,Overhead!$H:$H,Q$1,FALSE) -> 13184.231 | S27: =HLOOKUP($B$34,Overhead!$H:$H,S$1,FALSE) -> 836877.31 | T27: =HLOOKUP($B$34,Overhead!$H:$H,T$1,FALSE) -> 51127.211 | W27: =HLOOKUP($B$34,Overhead!$H:$H,W$1,FALSE) -> 102237.55 | Y27: =SUM(Y28:Y33) -> 4871983.4 | Z27: =+M27+P27+S27+V27 -> 1398886.8 | AA27: =+N27+Q27+T27+W27 -> 202534.9
A28: A00001 | B28: Induction Channel Assembly | C28: =SUMIF('Asset Allocation'!$F$1:$I$270,Calc!A28,'Asset Allocation'!I:I) -> 0 | D28: 20 | E28: A00001 | F28: =SUMIF(Wages!$O$2:$P$220,Calc!E28,Wages!$P$2:$P$220) -> 2 | G28: =SUMIF(Wages!$O$2:$AD$192,Calc!E28,Wages!$AD$2:$AD$192) -> 809046.09 | I28: 1.86 | J28: =+G28/L28 -> 3.5114848 | L28: =+F28*40*48*60 -> 230400 | M28: =+D28/$D$34*M$27 -> 29394.978 | N28: =+D28/$D$34*N$27 -> 1919.2484 | P28: =+P$27*$C28/$C$34 -> 0 | Q28: =+Q$27*$C28/$C$34 -> 0 | S28: =+L28/$L$34*$S$27 -> 134438.12 | T28: =+L28/$L$34*$T$27 -> 8213.2066 | W28: =+F28/$F$34*$W$27 -> 16423.703 | Y28: =+G28 -> 809046.09 | Z28: =+M28+P28+S28+V28 -> 163833.1 | AA28: =+N28+Q28+T28+W28 -> 26556.158 | AC28: =+Y28/L28 -> 3.5114848 | AD28: =+Z28/$L28 -> 0.71108116 | AE28: =+AA28/$L28 -> 0.1152611 | AF28: =SUM(AC28:AE28) -> 4.337827 | AG28: x | AH28: =+(ROUND(AF28,2)-AJ28)/AJ28 -> 0 | AJ28: =VLOOKUP(E28,Syspro!$A$2:$F$91,6,FALSE) -> 4.34 | AK28: 4.32 | AL28: 4.2523529 | AM28: 3.95 | AN28: 3.59 | AO28: 3.53 | AP28: 3.5422252 | AQ28: 3.27 | AR28: 3.08 | AS28: 3.08 | AT28: 3.09 | AU28: 3.02 | AV28: 3.18 | AW28: 2.9909304 | AX28: 2.8682207 | AY28: 3.39 | AZ28: 2.631129 | BB28: =(+AF28-AJ28)/AJ28 -> -0.00050068415
A29: A00002 | B29: Constant Volume Diffuser Ass | C29: =SUMIF('Asset Allocation'!$F$1:$I$270,Calc!A29,'Asset Allocation'!I:I) -> 0 | D29: 64 | E29: A00002 | F29: =SUMIF(Wages!$O$2:$P$220,Calc!E29,Wages!$P$2:$P$220) -> 2 | G29: =SUMIF(Wages!$O$2:$AD$192,Calc!E29,Wages!$AD$2:$AD$192) -> 807351.38 | I29: 1.86 | J29: =+G29/L29 -> 3.5041293 | L29: =+F29*40*48*60 -> 230400 | M29: =+D29/$D$34*M$27 -> 94063.928 | N29: =+D29/$D$34*N$27 -> 6141.5948 | P29: =+P$27*$C29/$C$34 -> 0 | Q29: =+Q$27*$C29/$C$34 -> 0 | S29: =+L29/$L$34*$S$27 -> 134438.12 | T29: =+L29/$L$34*$T$27 -> 8213.2066 | W29: =+F29/$F$34*$W$27 -> 16423.703 | Y29: =+G29 -> 807351.38 | Z29: =+M29+P29+S29+V29 -> 228502.05 | AA29: =+N29+Q29+T29+W29 -> 30778.505 | AC29: =+Y29/L29 -> 3.5041293 | AD29: =+Z29/$L29 -> 0.99176237 | AE29: =+AA29/$L29 -> 0.13358726 | AF29: =SUM(AC29:AE29) -> 4.6294789 | AG29: x | AH29: =+(ROUND(AF29,2)-AJ29)/AJ29 -> 0.0021645022 | AJ29: =VLOOKUP(E29,Syspro!$A$2:$F$91,6,FALSE) -> 4.62 | AK29: 4.61 | AL29: 4.5322075 | AM29: 4.3 | AN29: 3.75 | AO29: 3.69 | AP29: 3.6950899 | AQ29: 3.91 | AR29: 3.38 | AS29: 3.38 | AT29: 3.39 | AU29: 3.32 | AV29: 3.65 | AW29: 3.4427417 | AX29: 3.3196433 | AY29: 3.39 | AZ29: 2.631129 | BB29: =(+AF29-AJ29)/AJ29 -> 0.002051711
A30: A00003 | B30: Diffuser Sub-Assembly | C30: =SUMIF('Asset Allocation'!$F$1:$I$270,Calc!A30,'Asset Allocation'!I:I) -> 94000 | D30: 138 | E30: A00003 | F30: =SUMIF(Wages!$O$2:$P$220,Calc!E30,Wages!$P$2:$P$220) -> 3.95 | G30: =SUMIF(Wages!$O$2:$AD$192,Calc!E30,Wages!$AD$2:$AD$192) -> 1557753.8 | I30: 2.28 | J30: =+G30/L30 -> 3.4233338 | L30: =+F30*40*48*60 -> 455040 | M30: =+D30/$D$34*M$27 -> 202825.35 | N30: =+D30/$D$34*N$27 -> 13242.814 | P30: =+P$27*$C30/$C$34 -> 4399.114 | Q30: =+Q$27*$C30/$C$34 -> 5343.7435 | S30: =+L30/$L$34*$S$27 -> 265515.29 | T30: =+L30/$L$34*$T$27 -> 16221.083 | W30: =+F30/$F$34*$W$27 -> 32436.814 | Y30: =+G30 -> 1557753.8 | Z30: =+M30+P30+S30+V30 -> 472739.75 | AA30: =+N30+Q30+T30+W30 -> 67244.455 | AC30: =+Y30/L30 -> 3.4233338 | AD30: =+Z30/$L30 -> 1.0388971 | AE30: =+AA30/$L30 -> 0.14777702 | AF30: =SUM(AC30:AE30) -> 4.6100079 | AG30: x | AH30: =+(ROUND(AF30,2)-AJ30)/AJ30 -> 0 | AJ30: =VLOOKUP(E30,Syspro!$A$2:$F$91,6,FALSE) -> 4.61 | AK30: 4.59 | AL30: 4.51 | AM30: 4.4 | AN30: 3.95 | AO30: 3.89 | AP30: 3.8919537 | AQ30: 3.8 | AR30: 3.49 | AS30: 3.49 | AT30: 3.5 | AU30: 3.42 | AV30: 3.53 | AW30: 3.3276832 | AX30: 3.1238648 | AY30: 4.51 | AZ30: 3.8039549 | BB30: =(+AF30-AJ30)/AJ30 -> 1.713799e-06
A31: A00004 | B31: Diffuser Final Assembly & Sales Assembly | C31: =SUMIF('Asset Allocation'!$F$1:$I$270,Calc!A31,'Asset Allocation'!I:I) -> 0 | D31: 90 | E31: A00004 | F31: =SUMIF(Wages!$O$2:$P$220,Calc!E31,Wages!$P$2:$P$220) -> 2.7 | G31: =SUMIF(Wages!$O$2:$AD$192,Calc!E31,Wages!$AD$2:$AD$192) -> 1080353.9 | I31: 2.28 | J31: =+G31/L31 -> 3.47336 | L31: =+F31*40*48*60 -> 311040 | M31: =+D31/$D$34*M$27 -> 132277.4 | N31: =+D31/$D$34*N$27 -> 8636.6176 | P31: =+P$27*$C31/$C$34 -> 0 | Q31: =+Q$27*$C31/$C$34 -> 0 | S31: =+L31/$L$34*$S$27 -> 181491.46 | T31: =+L31/$L$34*$T$27 -> 11087.829 | W31: =+F31/$F$34*$W$27 -> 22172 | Y31: =+G31 -> 1080353.9 | Z31: =+M31+P31+S31+V31 -> 313768.86 | AA31: =+N31+Q31+T31+W31 -> 41896.446 | AC31: =+Y31/L31 -> 3.47336 | AD31: =+Z31/$L31 -> 1.0087734 | AE31: =+AA31/$L31 -> 0.13469794 | AF31: =SUM(AC31:AE31) -> 4.6168313 | AG31: x | AH31: =+(ROUNDUP(AF31,2)-AJ31)/AJ31 -> 0.0021691974 | AJ31: =VLOOKUP(E31,Syspro!$A$2:$F$91,6,FALSE) -> 4.61 | AK31: 4.6 | AL31: 4.5222124 | AM31: 4.59 | AN31: 3.84 | AO31: 3.78 | AP31: 3.7854809 | AQ31: 3.7 | AR31: 3.51 | AS31: 3.51 | AT31: 3.52 | AU31: 3.45 | AV31: 3.52 | AW31: 3.3135837 | AX31: 3.1122554 | AY31: 4.51 | AZ31: 3.8039549 | BB31: =(+AF31-AJ31)/AJ31 -> 0.0014818466
A32: A00005 | B32: Testing | C32: =SUMIF('Asset Allocation'!$F$1:$I$270,Calc!A32,'Asset Allocation'!I:I) -> 132500 | D32: 39 | E32: A00005 | F32: =SUMIF(Wages!$O$2:$P$220,Calc!E32,Wages!$P$2:$P$220) -> 0.8 | G32: =SUMIF(Wages!$O$2:$AD$192,Calc!E32,Wages!$AD$2:$AD$192) -> 335227.17 | I32: 2.28 | J32: =+G32/L32 -> 3.6374476 | L32: =+F32*40*48*60 -> 92160 | M32: =+D32/$D$34*M$27 -> 57320.206 | N32: =+D32/$D$34*N$27 -> 3742.5343 | P32: =+P$27*$C32/$C$34 -> 6200.8788 | Q32: =+Q$27*$C32/$C$34 -> 7532.4044 | S32: =+L32/$L$34*$S$27 -> 53775.249 | T32: =+L32/$L$34*$T$27 -> 3285.2827 | W32: =+F32/$F$34*$W$27 -> 6569.4814 | Y32: =+G32 -> 335227.17 | Z32: =+M32+P32+S32+V32 -> 117296.33 | AA32: =+N32+Q32+T32+W32 -> 21129.703 | AC32: 3.42 | AD32: 1.16 | AE32: =+AA32/$L32 -> 0.22927195 | AF32: =SUM(AC32:AE32) -> 4.8092719 | AG32: x | AH32: =+(ROUND(AF32,2)-AJ32)/AJ32 -> -1.8465248e-16 | AJ32: =VLOOKUP(E32,Syspro!$A$2:$F$91,6,FALSE) -> 4.81 | AK32: 4.82 | AL32: 4.78 | AM32: 4.78 | AN32: 4.09 | AO32: 4.03 | AP32: 4.0342803 | AQ32: 3.94 | AR32: 3.75 | AS32: 3.75 | AT32: 3.77 | AU32: 3.68 | AV32: 4.08 | AW32: 3.8571434 | AX32: 3.7718559 | AY32: 4.51 | AZ32: 3.8039549 | BB32: =(+AF32-AJ32)/AJ32 -> -0.00015136209
A33: A00006 | B33: QC | C33: =SUMIF('Asset Allocation'!$F$1:$I$270,Calc!A33,'Asset Allocation'!I:I) -> 5419.38 | D33: 24 | E33: A00006 | F33: =SUMIF(Wages!$O$2:$P$220,Calc!E33,Wages!$P$2:$P$220) -> 1 | G33: =SUMIF(Wages!$O$2:$AD$192,Calc!E33,Wages!$AD$2:$AD$192) -> 282251.1 | I33: 1.65 | J33: =+G33/L33 -> 2.4500963 | L33: =+F33*40*48*60 -> 115200 | M33: =+D33/$D$34*M$27 -> 35273.973 | N33: =+D33/$D$34*N$27 -> 2303.098 | P33: =+P$27*$C33/$C$34 -> 253.62203 | Q33: =+Q$27*$C33/$C$34 -> 308.08273 | S33: =+L33/$L$34*$S$27 -> 67219.061 | T33: =+L33/$L$34*$T$27 -> 4106.6033 | W33: =+F33/$F$34*$W$27 -> 8211.8517 | Y33: =+G33 -> 282251.1 | Z33: =+M33+P33+S33+V33 -> 102746.66 | AA33: =+N33+Q33+T33+W33 -> 14929.636 | AC33: =+Y33/L33 -> 2.4500963 | AD33: =+Z33/$L33 -> 0.89189805 | AE33: =+AA33/$L33 -> 0.12959753 | AF33: =SUM(AC33:AE33) -> 3.4715919 | AG33: x | AH33: =+(ROUND(AF33,2)-AJ33)/AJ33 -> 0 | AJ33: =VLOOKUP(E33,Syspro!$A$2:$F$91,6,FALSE) -> 3.47 | AK33: 3.45 | AL33: 3.3829586 | AM33: 3.21 | AN33: 2.79 | AO33: 2.84 | AP33: 2.8506451 | AQ33: 2.81 | AR33: 0 | AS33: 3.1 | AT33: 2.24 | AU33: 1.58 | AV33: 3.64 | AW33: 3.4903804 | AX33: 3.2799387 | AZ33: 1.65 | BB33: =(+AF33-AJ33)/AJ33 -> 0.00045876193
B34: Assembly | C34: =SUM(C28:C33) -> 231919.38 | D34: =SUM(D28:D33) -> 375 | F34: =SUM(F28:F33) -> 12.45 | L34: =SUM(L28:L33) -> 1434240 | AB34: x
B35: Pretoria | M35: =HLOOKUP($B$37,Overhead!$I:$I,M$1,FALSE) -> 529697.11 | N35: =HLOOKUP($B$37,Overhead!$I:$I,N$1,FALSE) -> 518.85434 | P35: =HLOOKUP($B$37,Overhead!$I:$I,P$1,FALSE) -> 5426.8075 | Q35: =HLOOKUP($B$37,Overhead!$I:$I,Q$1,FALSE) -> 0 | S35: =HLOOKUP($B$37,Overhead!$I:$I,S$1,FALSE) -> 271159.78 | T35: =HLOOKUP($B$37,Overhead!$I:$I,T$1,FALSE) -> 133793.4 | W35: =HLOOKUP($B$37,Overhead!$I:$I,W$1,FALSE) -> 17932.979
A36: 01PTA | B36: Assembly | C36: =SUMIF('Asset Allocation'!$F$1:$I$270,Calc!A36,'Asset Allocation'!I:I) -> 45877.23 | D36: 150 | E36: 01PTA | F36: =SUMIF(Wages!$O$2:$P$190,Calc!E36,Wages!$P$2:$P$190) -> 2 | G36: =SUMIF(Wages!$O$2:$AD$192,Calc!E36,Wages!$AD$2:$AD$192) -> 374336.1 | I36: 2.33 | J36: =+G36/L36 -> 1.6247227 | L36: =+F36*40*48*60 -> 230400 | M36: =+$D36/$D$37*M$35 -> 529697.11 | N36: =+D36/$D$37*N$35 -> 518.85434 | P36: =+P$35*$C36/$C$34 -> 1073.5062 | Q36: =+Q$35*$C36/$C$34 -> 0 | S36: =+L36/$L$37*$S$35 -> 271159.78 | T36: =+L36/$L$37*$T$35 -> 133793.4 | W36: =+F36/$F$37*$W$35 -> 17932.979 | Y36: =+G36 -> 374336.1 | Z36: =+M36+P36+S36+V36 -> 801930.39 | AA36: =+N36+Q36+T36+W36 -> 152245.23 | AC36: =+Y36/L36 -> 1.6247227 | AD36: =+Z36/$L36 -> 3.4806007 | AE36: =+AA36/$L36 -> 0.6607866 | AF36: =SUM(AC36:AE36) -> 5.76611 | AH36: =+(AF36-AJ36)/AJ36 -> 0.0010607553 | AJ36: =VLOOKUP(E36,Syspro!$A$2:$F$91,6,FALSE) -> 5.76 | AK36: 5.5 | AL36: 5.1113402 | AM36: 5.07 | AN36: 4.91 | AO36: 4.83 | AP36: 4.8307509 | AQ36: 4.96 | AR36: 5.94 | AS36: 5.94 | AT36: 5.75 | AU36: 5.66 | AV36: 5.84 | AW36: 5.2677184 | AX36: 5.6428628 | AZ36: 2.22 | BB36: =(+AF36-AJ36)/AJ36 -> 0.0010607553
B37: AssemblyPTA | C37: =SUM(C36) -> 45877.23 | D37: =SUM(D36) -> 150 | F37: =SUM(F36) -> 2 | L37: =SUM(L36) -> 230400
A39: Damper | E39: Damper | M39: =HLOOKUP($B$48,Overhead!$J:$J,M$1,FALSE) -> 500440.73 | N39: =HLOOKUP($B$48,Overhead!$J:$J,N$1,FALSE) -> 32674.704 | P39: =HLOOKUP($B$48,Overhead!$J:$J,P$1,FALSE) -> 21707.23 | Q39: =HLOOKUP($B$48,Overhead!$J:$J,Q$1,FALSE) -> 37217.095 | S39: =HLOOKUP($B$48,Overhead!$J:$J,S$1,FALSE) -> 565717.53 | T39: =HLOOKUP($B$48,Overhead!$J:$J,T$1,FALSE) -> 128528.01 | W39: =HLOOKUP($B$48,Overhead!$J:$J,W$1,FALSE) -> 82118.517 | Y39: =SUM(Y40:Y47) -> 4089933.9 | Z39: =+M39+P39+S39+V39 -> 1087865.5 | AA39: =+N39+Q39+T39+W39 -> 280538.33
A40: D00001 | B40: Cutting | C40: =SUMIF('Asset Allocation'!$F$2:$I$269,Calc!$A40,'Asset Allocation'!$I$2:$I$269) -> 61401.58 | D40: 83 | E40: D00001 | F40: =SUMIF(Wages!$O$2:$P$220,Calc!E40,Wages!$P$2:$P$220) -> 3 | G40: =SUMIF(Wages!$O$2:$AD$192,Calc!E40,Wages!$AD$2:$AD$192) -> 1276708.4 | I40: 2.31 | J40: =+G40/L40 -> 3.6941793 | L40: =+F40*40*48*60 -> 345600 | M40: =+$D40/$D$48*M$39 -> 91289.188 | N40: =+$D40/$D$48*N$39 -> 5960.4404 | P40: =+P$39*$C40/$C$48 -> 2035.9131 | Q40: =+Q$39*$C40/$C$48 -> 3490.5776 | S40: =+$S$39*L40/$L$48 -> 169715.26 | T40: =+$T$39*L40/$L$48 -> 38558.404 | W40: =+$W$39*F40/$F$48 -> 24635.555 | Y40: =+G40 -> 1276708.4 | Z40: =+M40+P40+S40+V40 -> 263040.36 | AA40: =+N40+Q40+T40+W40 -> 72644.977 | AC40: =+Y40/L40 -> 3.6941793 | AD40: =+Z40/$L40 -> 0.76111215 | AE40: =+AA40/$L40 -> 0.21019959 | AF40: =SUM(AC40:AE40) -> 4.665491 | AG40: x | AH40: =+(ROUND(AF40,2)-AJ40)/AJ40 -> 0.0021459227 | AJ40: =VLOOKUP(E40,Syspro!$A$2:$F$91,6,FALSE) -> 4.66 | AK40: 4.64 | AL40: 4.73 | AM40: 4.15 | AN40: 5.21 | AO40: 5.1 | AP40: 5.0929133 | AQ40: 4.95 | AR40: 4.96 | AS40: 4.96 | AT40: 5.08 | AU40: 4.65 | AV40: 4.61 | AW40: 4.3082856 | AX40: 4.2295808 | AY40: 3.11 | AZ40: 2.68 | BB40: =(+AF40-AJ40)/AJ40 -> 0.0011783247
A41: D00002 | B41: Brushing | C41: =SUMIF('Asset Allocation'!$F$1:$I$270,Calc!A41,'Asset Allocation'!I:I) -> 0 | D41: 7 | E41: D00002 | F41: =SUMIF(Wages!$O$2:$P$220,Calc!E41,Wages!$P$2:$P$220) -> 0.2 | G41: =SUMIF(Wages!$O$2:$AD$192,Calc!E41,Wages!$AD$2:$AD$192) -> 85941.062 | I41: 2.31 | J41: =+G41/L41 -> 3.7300808 | L41: =+F41*40*48*60 -> 23040 | M41: =+$D41/$D$48*M$39 -> 7699.0882 | N41: =+$D41/$D$48*N$39 -> 502.68775 | P41: =+P$39*$C41/$C$48 -> 0 | Q41: =+Q$39*$C41/$C$48 -> 0 | S41: =+$S$39*L41/$L$48 -> 11314.351 | T41: =+$T$39*L41/$L$48 -> 2570.5602 | W41: =+$W$39*F41/$F$48 -> 1642.3703 | Y41: =+G41 -> 85941.062 | Z41: =+M41+P41+S41+V41 -> 19013.439 | AA41: =+N41+Q41+T41+W41 -> 4715.6183 | AC41: =+Y41/L41 -> 3.7300808 | AD41: =+Z41/$L41 -> 0.82523606 | AE41: =+AA41/$L41 -> 0.20467093 | AF41: =SUM(AC41:AE41) -> 4.7599878 | AG41: x | AH41: =+(ROUND(AF41,2)-AJ41)/AJ41 -> 0 | AJ41: =VLOOKUP(E41,Syspro!$A$2:$F$91,6,FALSE) -> 4.76 | AK41: 4.73 | AL41: 4.66 | AM41: 4.25 | AN41: 4.87 | AO41: 4.76 | AP41: 4.7542743 | AQ41: 4.62 | AR41: 4.6 | AS41: 4.6 | AT41: 4.73 | AU41: 4.3 | AV41: 5.23 | AW41: 4.8896709 | AX41: 4.7829864 | AY41: 3.11 | AZ41: 2.68 | BB41: =(+AF41-AJ41)/AJ41 -> -2.5630787e-06
A42: D00003 | B42: Notching | C42: =SUMIF('Asset Allocation'!$F$1:$I$270,Calc!A42,'Asset Allocation'!I:I) -> 5647.83 | D42: 7 | E42: D00003 | F42: =SUMIF(Wages!$O$2:$P$220,Calc!E42,Wages!$P$2:$P$220) -> 0.65 | G42: =SUMIF(Wages!$O$2:$AD$192,Calc!E42,Wages!$AD$2:$AD$192) -> 274244.19 | I42: 2.31 | J42: =+G42/L42 -> 3.6624492 | L42: =+F42*40*48*60 -> 74880 | M42: =+$D42/$D$48*M$39 -> 7699.0882 | N42: =+$D42/$D$48*N$39 -> 502.68775 | P42: =+P$39*$C42/$C$48 -> 187.26702 | Q42: =+Q$39*$C42/$C$48 -> 321.06973 | S42: =+$S$39*L42/$L$48 -> 36771.639 | T42: =+$T$39*L42/$L$48 -> 8354.3208 | W42: =+$W$39*F42/$F$48 -> 5337.7036 | Y42: =+G42 -> 274244.19 | Z42: =+M42+P42+S42+V42 -> 44657.995 | AA42: =+N42+Q42+T42+W42 -> 14515.782 | AC42: =+Y42/L42 -> 3.6624492 | AD42: =+Z42/$L42 -> 0.59639416 | AE42: =+AA42/$L42 -> 0.19385392 | AF42: =SUM(AC42:AE42) -> 4.4526973 | AG42: x | AH42: =+(ROUND(AF42,2)-AJ42)/AJ42 -> 0 | AJ42: =VLOOKUP(E42,Syspro!$A$2:$F$91,6,FALSE) -> 4.45 | AK42: 4.43 | AL42: 4.36 | AM42: 3.77 | AN42: 4.9 | AO42: 4.78 | AP42: 4.7818603 | AQ42: 4.64 | AR42: 4.64 | AS42: 4.64 | AT42: 4.77 | AU42: 4.34 | AV42: 5.31 | AW42: 4.9671274 | AX42: 4.7829864 | AY42: 3.11 | AZ42: 2.68 | BB42: =(+AF42-AJ42)/AJ42 -> 0.00060612599
...

Sheet Asset Allocation
A1: PTA | K1: Lansdowne Asset recon | O1: Years SinceBought | P1: Average Age x Price to get Weighting for R&M | Q1: Sensitivity to Breakdowns(Scale1-5)
A2: P&M782 | B2: Compressor and Riveter | C2: 42217 | D2: 6057.02 | F2: 01PTA | G2: Pta | H2: 1 | I2: =+D2*H2 -> 6057.02 | N2: =NOW() -> 46204.531 | O2: =_xlfn.DAYS(N2,C2)/365 -> 10.923288 | P2: =+O2*I2 -> 66162.572
A3: P&M823 | B3: Electrical Fan | C3: 42644 | D3: 12116.23 | F3: 01PTA | G3: Pta | H3: 1 | I3: =+D3*H3 -> 12116.23 | N3: =NOW() -> 46204.531 | O3: =_xlfn.DAYS(N3,C3)/365 -> 9.7534247 | P3: =+O3*I3 -> 118174.74
A4: F&F654 | B4: Container and Shelves | C4: 40848 | D4: 27703.98 | F4: 01PTA | G4: Pta | H4: 1 | I4: =+D4*H4 -> 27703.98 | N4: =NOW() -> 46204.531 | O4: =_xlfn.DAYS(N4,C4)/365 -> 14.673973 | P4: =+O4*I4 -> 406527.44
C5: PTAWET | I5: =SUM(I2:I4) -> 45877.23 | Q5: 1 | R5: =SUM(P2:P4)*Q5 -> 590864.75 | S5: =+R5/$R$338 -> 0.0011013506
A6: Trumpf
A7: P&M697 | B7: Trumpf CNC Press | C7: 41275 | D7: 3626679 | F7: 05 | G7: Ott | H7: 1 | I7: =+D7*H7 -> 3626679 | N7: =NOW() -> 46204.531 | O7: =_xlfn.DAYS(N7,C7)/365 -> 13.50411 | P7: =+O7*I7 -> 48975071
A8: P&M792 | B8: Air Dryer and Drains | C8: 42370 | D8: 124550 | F8: 05 | G8: Ott | H8: 1 | I8: =+D8*H8 -> 124550 | N8: =NOW() -> 46204.531 | O8: =_xlfn.DAYS(N8,C8)/365 -> 10.50411 | P8: =+O8*I8 -> 1308286.8
A9: P&M804 | B9: Reconnecting Air Dryer and Piping | C9: 42430 | D9: 33923 | F9: 05 | G9: Ott | H9: 1 | I9: =+D9*H9 -> 33923 | N9: =NOW() -> 46204.531 | O9: =_xlfn.DAYS(N9,C9)/365 -> 10.339726 | P9: =+O9*I9 -> 350754.53
A10: P&M812 | B10: Air Dryer Trumpf | C10: 42522 | D10: 15057 | F10: 05 | G10: Ott | H10: 1 | I10: =+D10*H10 -> 15057 | N10: =NOW() -> 46204.531 | O10: =_xlfn.DAYS(N10,C10)/365 -> 10.087671 | P10: =+O10*I10 -> 151890.07
A11: TOO610 | B11: Die and Punches as per INV23442 | C11: 40238 | D11: 10735 | F11: 05 | G11: Ott | H11: 1 | I11: =+D11*H11 -> 10735 | N11: =NOW() -> 46204.531 | O11: =_xlfn.DAYS(N11,C11)/365 -> 16.345205 | P11: =+O11*I11 -> 175465.78
A12: TOO621 | B12: 1KVA UPS | C12: 40330 | D12: 2707.5 | F12: 05 | G12: Ott | H12: 1 | I12: =+D12*H12 -> 2707.5 | N12: =NOW() -> 46204.531 | O12: =_xlfn.DAYS(N12,C12)/365 -> 16.093151 | P12: =+O12*I12 -> 43572.205
A13: TOO696 | B13: Various Trumf tools 30 000 Eur | C13: 41275 | D13: 327210 | F13: 05 | G13: Ott | H13: 1 | I13: =+D13*H13 -> 327210 | N13: =NOW() -> 46204.531 | O13: =_xlfn.DAYS(N13,C13)/365 -> 13.50411 | P13: =+O13*I13 -> 4418679.7
A14: TOO711 | B14: Louvre Tool - Trumpf | C14: 41365 | D14: 12898 | F14: 05 | G14: Ott | H14: 1 | I14: =+D14*H14 -> 12898 | N14: =NOW() -> 46204.531 | O14: =_xlfn.DAYS(N14,C14)/365 -> 13.257534 | P14: =+O14*I14 -> 170995.68
A15: TOO721 | B15: Roll Splitting Tool | C15: 41456 | D15: 39817 | F15: 05 | G15: Ott | H15: 1 | I15: =+D15*H15 -> 39817 | N15: =NOW() -> 46204.531 | O15: =_xlfn.DAYS(N15,C15)/365 -> 13.008219 | P15: =+O15*I15 -> 517948.26
A16: TOO739 | B16: Trumpf Tooling | C16: 41730 | D16: 8800 | F16: 05 | G16: Ott | H16: 1 | I16: =+D16*H16 -> 8800 | N16: =NOW() -> 46204.531 | O16: =_xlfn.DAYS(N16,C16)/365 -> 12.257534 | P16: =+O16*I16 -> 107866.3
A17: TOO777 | B17: Roller Cutting Tool | C17: 42156 | D17: 19300 | F17: 05 | G17: Ott | H17: 1 | I17: =+D17*H17 -> 19300 | N17: =NOW() -> 46204.531 | O17: =_xlfn.DAYS(N17,C17)/365 -> 11.090411 | P17: =+O17*I17 -> 214044.93
A18: TOO961 | B18: Trumph Additional set Dies & punches | C18: 43556 | D18: 22380 | F18: 05 | G18: Ott | H18: 1 | I18: =+D18*H18 -> 22380 | N18: =NOW() -> 46204.531 | O18: =_xlfn.DAYS(N18,C18)/365 -> 7.2547945 | P18: =+O18*I18 -> 162362.3
... A20: TOO802 | B20: VRD Outer Edge | C20: 42401 | D20: 35000 | F20: 05 | G20: Ott | H20: 1 | I20: =+D20*H20 -> 35000 | N20: =NOW() -> 46204.531 | O20: =_xlfn.DAYS(N20,C20)/365 -> 10.419178 | P20: =+O20*I20 -> 364671.23
C21: Trumpf | I21: =SUM(I7:I20) -> 4317281 | J21: x | K21: =+I21 -> 4317281 | Q21: 4 | R21: =SUM(P7:P20)*Q21 -> 2.2870015e+08 | S21: =+R21/$R$338 -> 0.42628885
A22: DiffuserAssembly
A23: TOO459 | B23: Bayonet Fitting | C23: 39387 | D23: 94000 | F23: A00003 | G23: Lan | H23: 1 | I23: =+D23*H23 -> 94000 | N23: =NOW() -> 46204.531 | O23: =_xlfn.DAYS(N23,C23)/365 -> 18.676712 | P23: =+O23*I23 -> 1755611
A24: TOO349 | B24: SPINNING DIE/JIG SWIRL PLATE | C24: 38565 | D24: 2900 | F24: A00005 | G24: Lan | H24: 1 | I24: =+D24*H24 -> 2900 | N24: =NOW() -> 46204.531 | O24: =_xlfn.DAYS(N24,C24)/365 -> 20.928767 | P24: =+O24*I24 -> 60693.425
A25: TOO350 | B25: SPINNING DIE/JIG MED SWIRL Rnd | C25: 38565 | D25: 2900 | F25: A00005 | G25: Lan | H25: 1 | I25: =+D25*H25 -> 2900 | N25: =NOW() -> 46204.531 | O25: =_xlfn.DAYS(N25,C25)/365 -> 20.928767 | P25: =+O25*I25 -> 60693.425
A26: TOO450 | B26: Wall Stat Design and Mould | C26: 39326 | D26: 126700 | F26: A00005 | G26: Lan | H26: 1 | I26: =+D26*H26 -> 126700 | N26: =NOW() -> 46204.531 | O26: =_xlfn.DAYS(N26,C26)/365 -> 18.843836 | P26: =+O26*I26 -> 2387514
A27: T00151 | B27: Vortex Testing Tubes | C27: 37288 | D27: 5419.38 | F27: A00006 | G27: Lan | H27: 1 | I27: =+D27*H27 -> 5419.38 | N27: =NOW() -> 46204.531 | O27: =_xlfn.DAYS(N27,C27)/365 -> 24.427397 | P27: =+O27*I27 -> 132381.35
C28: Assembly | I28: =SUM(I23:I27) -> 231919.38 | J28: x | K28: =+I28 -> 231919.38 | Q28: 1 | R28: =SUM(P14:P27)*Q28 -> 6148210.7 | S28: =+R28/$R$338 -> 0.011460044
A31: Dampers
A32: TOO443 | B32: Mitre Saw LS101034 | C32: 39173 | D32: 7850 | F32: D00001 | G32: Ott | H32: 1 | I32: =+D32*H32 -> 7850 | N32: =NOW() -> 46204.531 | O32: =_xlfn.DAYS(N32,C32)/365 -> 19.263014 | P32: =+O32*I32 -> 151214.66
A33: TOO453 | B33: VLN Piercing Tool | C33: 39326 | D33: 8770 | F33: D00001 | G33: Ott | H33: 1 | I33: =+D33*H33 -> 8770 | N33: =NOW() -> 46204.531 | O33: =_xlfn.DAYS(N33,C33)/365 -> 18.843836 | P33: =+O33*I33 -> 165260.44
A34: TOO904 | B34: Makita slide Mitre Saw (Damper dept) | C34: 43040 | D34: 7578.11 | F34: D00001 | G34: Ott | H34: 1 | I34: =+D34*H34 -> 7578.11 | N34: =NOW() -> 46204.531 | O34: =_xlfn.DAYS(N34,C34)/365 -> 8.6684932 | P34: =+O34*I34 -> 65690.795
A35: TOO985 | B35: GCM 12GDL Gliding/Sliding double bevel saw | C35: 44075 | D35: 13042.61 | F35: D00001 | H35: 1 | I35: =+D35*H35 -> 13042.61 | N35: =NOW() -> 46204.531 | O35: =_xlfn.DAYS(N35,C35)/365 -> 5.8328767 | P35: =+O35*I35 -> 76075.936
A36: TOO937 | B36: 1.6mm Notching Machine | C36: 43282 | D36: 5647.83 | F36: D00003 | G36: Ott | H36: 1 | I36: =+D36*H36 -> 5647.83 | N36: =NOW() -> 46204.531 | O36: =_xlfn.DAYS(N36,C36)/365 -> 8.0054795 | P36: =+O36*I36 -> 45213.587
A37: P&M647 | B37: Aliminium Welder | C37: 40787 | D37: 11135 | F37: D00004 | G37: Ott | H37: 1 | I37: =+D37*H37 -> 11135 | N37: =NOW() -> 46204.531 | O37: =_xlfn.DAYS(N37,C37)/365 -> 14.841096 | P37: =+O37*I37 -> 165255.6
A38: P&M713 | B38: Tig Welder | C38: 41395 | D38: 8000 | F38: D00004 | G38: Ott | H38: 1 | I38: =+D38*H38 -> 8000 | N38: =NOW() -> 46204.531 | O38: =_xlfn.DAYS(N38,C38)/365 -> 13.175342 | P38: =+O38*I38 -> 105402.74
A39: TOO495 | B39: ALUMINIUM TIG WELDER | C39: 39539 | D39: 9188 | F39: D00004 | G39: Ott | H39: 1 | I39: =+D39*H39 -> 9188 | N39: =NOW() -> 46204.531 | O39: =_xlfn.DAYS(N39,C39)/365 -> 18.260274 | P39: =+O39*I39 -> 167775.4
A40: P&M365 | B40: PNEUMATIC RIVETER | C40: 38626 | D40: 4672.24 | F40: D00004 | H40: 1 | I40: =+D40*H40 -> 4672.24 | N40: =NOW() -> 46204.531 | O40: =_xlfn.DAYS(N40,C40)/365 -> 20.761644 | P40: =+O40*I40 -> 97003.383
A41: TOO422 | B41: Power Fastner - For RA Griles | C41: 39142 | D41: 22797 | F41: D00005 | G41: Ott | H41: 1 | I41: =+D41*H41 -> 22797 | N41: =NOW() -> 46204.531 | O41: =_xlfn.DAYS(N41,C41)/365 -> 19.347945 | P41: =+O41*I41 -> 441075.11
A42: TOO439 | B42: Extrusion Radius Notching Tool | C42: 39264 | D42: 5470 | F42: D00005 | G42: Ott | H42: 1 | I42: =+D42*H42 -> 5470 | N42: =NOW() -> 46204.531 | O42: =_xlfn.DAYS(N42,C42)/365 -> 19.013699 | P42: =+O42*I42 -> 104004.93
A43: TOO683 | B43: Electric Crimper | C43: 41183 | D43: 9500 | F43: D00005 | G43: Ott | H43: 1 | I43: =+D43*H43 -> 9500 | N43: =NOW() -> 46204.531 | O43: =_xlfn.DAYS(N43,C43)/365 -> 13.756164 | P43: =+O43*I43 -> 130683.56
...

Sheet Wages
A1: Damper | J1: Efficiency | L1: Workcentres | P1: Time Allocation | Q1: Amnt per Hour | S1: Annual | T1: Bonus | U1: GainShare | V1: UIF | W1: Pension | X1: Sick Pay Fund | Y1: Dispute Levy | Z1: ADM and TEC Levy | AA1: SDL | AB1: Total | AC1: Efficiency | AD1: Amnt
A2: W0000066 | B2: Leslie | C2: Basson | D2: 7711115085081 | E2: M | F2: C | G2: Damper Cutting/Set-up Assem | H2: DAMPER | I2: 72.85 | J2: 0.5 | K2: OTT | L2: Damper Assembly | M2: 0.45 | O2: D00006 | P2: =+M2 -> 0.45 | Q2: =+$I$2*P2 -> 32.7825 | S2: =+Q2*40*52 -> 68187.6 | T2: =+S2*0.0833 -> 5680.0271 | U2: =+T2 -> 5680.0271 | V2: =+S2*0.01 -> 681.876 | W2: =+S2*0.083 -> 5659.5708 | X2: =+S2*0.0018 -> 122.73768 | Y2: =0.71*52*P2 -> 16.614 | Z2: =172*12*P2 -> 928.8 | AA2: =+(S2+T2+U2)*0.01 -> 795.47654 | AB2: =SUM(S2:AA2) -> 87752.729 | AC2: =IF(+J2>0,J2,AC1) -> 0.5 | AD2: =+AB2/AC2 -> 175505.46
K3: OTT | L3: Cutting | M3: 0.45 | O3: D00001 | P3: =+M3 -> 0.45 | Q3: =+$I$2*P3 -> 32.7825 | S3: =+Q3*40*52 -> 68187.6 | T3: =+S3*0.0833 -> 5680.0271 | U3: =+T3 -> 5680.0271 | V3: =+S3*0.01 -> 681.876 | W3: =+S3*0.083 -> 5659.5708 | X3: =+S3*0.0018 -> 122.73768 | Y3: =0.71*52*P3 -> 16.614 | Z3: =172*12*P3 -> 928.8 | AA3: =+(S3+T3+U3)*0.01 -> 795.47654 | AB3: =SUM(S3:AA3) -> 87752.729 | AC3: =IF(+J3>0,J3,AC2) -> 0.5 | AD3: =+AB3/AC3 -> 175505.46
K4: OTT | L4: Notching | M4: 0.1 | O4: D00003 | P4: =+M4 -> 0.1 | Q4: =+$I$2*P4 -> 7.285 | S4: =+Q4*40*52 -> 15152.8 | T4: =+S4*0.0833 -> 1262.2282 | U4: =+T4 -> 1262.2282 | V4: =+S4*0.01 -> 151.528 | W4: =+S4*0.083 -> 1257.6824 | X4: =+S4*0.0018 -> 27.27504 | Y4: =0.71*52*P4 -> 3.692 | Z4: =172*12*P4 -> 206.4 | AA4: =+(S4+T4+U4)*0.01 -> 176.77256 | AB4: =SUM(S4:AA4) -> 19500.606 | AC4: =IF(+J4>0,J4,AC3) -> 0.5 | AD4: =+AB4/AC4 -> 39001.213
A6: W0000022 | B6: Dale | C6: Fortune | E6: M | F6: C | G6: Leading Hand/Damper Assembl | H6: DAMPER | I6: 109.2 | J6: 0.75 | K6: OTT | L6: Damper Assembly | M6: 0.7 | O6: D00006 | P6: =+M6 -> 0.7 | Q6: =+I6*P6 -> 76.44 | S6: =+Q6*40*52 -> 158995.2 | T6: =+S6*0.0833 -> 13244.3 | U6: =+T6 -> 13244.3 | V6: =+S6*0.01 -> 1589.952 | W6: =+S6*0.083 -> 13196.602 | X6: =+S6*0.0018 -> 286.19136 | Y6: =0.71*52*P6 -> 25.844 | Z6: =172*12*P6 -> 1444.8 | AA6: =+(S6+T6+U6)*0.01 -> 1854.838 | AB6: =SUM(S6:AA6) -> 203882.03 | AC6: =IF(+J6>0,J6,AC5) -> 0.75 | AD6: =+AB6/AC6 -> 271842.7
K7: OTT | L7: Cutting | M7: 0.3 | O7: D00001 | P7: =+M7 -> 0.3 | Q7: =+$I$6*P7 -> 32.76 | S7: =+Q7*40*52 -> 68140.8 | T7: =+S7*0.0833 -> 5676.1286 | U7: =+T7 -> 5676.1286 | V7: =+S7*0.01 -> 681.408 | W7: =+S7*0.083 -> 5655.6864 | X7: =+S7*0.0018 -> 122.65344 | Y7: =0.71*52*P7 -> 11.076 | Z7: =172*12*P7 -> 619.2 | AA7: =+(S7+T7+U7)*0.01 -> 794.93057 | AB7: =SUM(S7:AA7) -> 87378.012 | AC7: =IF(+J7>0,J7,AC6) -> 0.75 | AD7: =+AB7/AC7 -> 116504.02
A9: CON389 | B9: Petula | C9: Amos | E9: F | F9: C | G9: Damper Assembler | H9: DAMPER | I9: 89.52 | J9: 0.5 | K9: OTT | L9: Testing | M9: 0.3 | O9: D00007 | P9: =+M9 -> 0.3 | Q9: =+$I$9*P9 -> 26.856 | S9: =+Q9*40*52 -> 55860.48 | T9: =+S9*0.0833 -> 4653.178 | U9: =+T9 -> 4653.178 | V9: =+S9*0.01 -> 558.6048 | W9: =+S9*0.083 -> 4636.4198 | X9: =+S9*0.0018 -> 100.54886 | Y9: =0.71*52*P9 -> 11.076 | Z9: =172*12*P9 -> 619.2 | AA9: =+(S9+T9+U9)*0.01 -> 651.66836 | AB9: =SUM(S9:AA9) -> 71744.354 | AC9: =IF(+J9>0,J9,AC8) -> 0.5 | AD9: =+AB9/AC9 -> 143488.71
K10: OTT | L10: Damper Assembly | M10: 0.3 | O10: D00006 | P10: =+M10 -> 0.3 | Q10: =+$I$9*P10 -> 26.856 | S10: =+Q10*40*52 -> 55860.48 | T10: =+S10*0.0833 -> 4653.178 | U10: =+T10 -> 4653.178 | V10: =+S10*0.01 -> 558.6048 | W10: =+S10*0.083 -> 4636.4198 | X10: =+S10*0.0018 -> 100.54886 | Y10: =0.71*52*P10 -> 11.076 | Z10: =172*12*P10 -> 619.2 | AA10: =+(S10+T10+U10)*0.01 -> 651.66836 | AB10: =SUM(S10:AA10) -> 71744.354 | AC10: =IF(+J10>0,J10,AC9) -> 0.5 | AD10: =+AB10/AC10 -> 143488.71
K11: OTT | L11: Notching | M11: 0.1 | O11: D00003 | P11: =+M11 -> 0.1 | Q11: =+$I$9*P11 -> 8.952 | S11: =+Q11*40*52 -> 18620.16 | T11: =+S11*0.0833 -> 1551.0593 | U11: =+T11 -> 1551.0593 | V11: =+S11*0.01 -> 186.2016 | W11: =+S11*0.083 -> 1545.4733 | X11: =+S11*0.0018 -> 33.516288 | Y11: =0.71*52*P11 -> 3.692 | Z11: =172*12*P11 -> 206.4 | AA11: =+(S11+T11+U11)*0.01 -> 217.22279 | AB11: =SUM(S11:AA11) -> 23914.785 | AC11: =IF(+J11>0,J11,AC10) -> 0.5 | AD11: =+AB11/AC11 -> 47829.569
K12: OTT | L12: Grille Assembly | M12: 0.3 | O12: D00005 | P12: =+M12 -> 0.3 | Q12: =+$I$9*P12 -> 26.856 | S12: =+Q12*40*52 -> 55860.48 | T12: =+S12*0.0833 -> 4653.178 | U12: =+T12 -> 4653.178 | V12: =+S12*0.01 -> 558.6048 | W12: =+S12*0.083 -> 4636.4198 | X12: =+S12*0.0018 -> 100.54886 | Y12: =0.71*52*P12 -> 11.076 | Z12: =172*12*P12 -> 619.2 | AA12: =+(S12+T12+U12)*0.01 -> 651.66836 | AB12: =SUM(S12:AA12) -> 71744.354 | AC12: =IF(+J12>0,J12,AC10) -> 0.5 | AD12: =+AB12/AC12 -> 143488.71
A15: CON469B | B15: Reuben | C15: Presence | E15: M | F15: C | G15: Welder/Damper Assembler | H15: DAMPER | I15: 87.84 | J15: 0.5 | K15: OTT | L15: Cutting | M15: 0.5 | O15: D00001 | P15: =+M15 -> 0.5 | Q15: =+$I$15*P15 -> 43.92 | S15: =+Q15*40*52 -> 91353.6 | T15: =+S15*0.0833 -> 7609.7549 | U15: =+T15 -> 7609.7549 | V15: =+S15*0.01 -> 913.536 | W15: =+S15*0.083 -> 7582.3488 | X15: =+S15*0.0018 -> 164.43648 | Y15: =0.71*52*P15 -> 18.46 | Z15: =172*12*P15 -> 1032 | AA15: =+(S15+T15+U15)*0.01 -> 1065.7311 | AB15: =SUM(S15:AA15) -> 117349.62 | AC15: =IF(+J15>0,J15,AC14) -> 0.5 | AD15: =+AB15/AC15 -> 234699.24
L16: Welding | M16: 0.4 | O16: D00004 | P16: =+M16 -> 0.4 | Q16: =+$I$15*P16 -> 35.136 | S16: =+Q16*40*52 -> 73082.88 | T16: =+S16*0.0833 -> 6087.8039 | U16: =+T16 -> 6087.8039 | V16: =+S16*0.01 -> 730.8288 | W16: =+S16*0.083 -> 6065.879 | X16: =+S16*0.0018 -> 131.54918 | Y16: =0.71*52*P16 -> 14.768 | Z16: =172*12*P16 -> 825.6 | AA16: =+(S16+T16+U16)*0.01 -> 852.58488 | AB16: =SUM(S16:AA16) -> 93879.698 | AC16: =+AC15 -> 0.5 | AD16: =+AB16/AC16 -> 187759.4
L17: Brushing | M17: 0.1 | O17: D00002 | P17: =+M17 -> 0.1 | Q17: =+$I$15*P17 -> 8.784 | S17: =+Q17*40*52 -> 18270.72 | T17: =+S17*0.0833 -> 1521.951 | U17: =+T17 -> 1521.951 | V17: =+S17*0.01 -> 182.7072 | W17: =+S17*0.083 -> 1516.4698 | X17: =+S17*0.0018 -> 32.887296 | Y17: =0.71*52*P17 -> 3.692 | Z17: =172*12*P17 -> 206.4 | AA17: =+(S17+T17+U17)*0.01 -> 213.14622 | AB17: =SUM(S17:AA17) -> 23469.924 | AC17: =IF(+J17>0,J17,AC15) -> 0.5 | AD17: =+AB17/AC17 -> 46939.849
A19: CON184A | B19: Goodman | C19: Puza | E19: M | F19: A | G19: Welding/Damper Assembly | H19: DAMPER | I19: 81.61 | J19: 0.5 | K19: OTT | L19: Welding | M19: 1 | O19: D00004 | P19: =+M19 -> 1 | Q19: =+I19*P19 -> 81.61 | S19: =+Q19*40*52 -> 169748.8 | T19: =+S19*0.0833 -> 14140.075 | U19: =+T19 -> 14140.075 | V19: =+S19*0.01 -> 1697.488 | W19: =+S19*0.083 -> 14089.15 | X19: =+S19*0.0018 -> 305.54784 | Y19: =0.71*52*P19 -> 36.92 | Z19: =172*12*P19 -> 2064 | AA19: =+(S19+T19+U19)*0.01 -> 1980.2895 | AB19: =SUM(S19:AA19) -> 218202.35 | AC19: =IF(+J19>0,J19,AC18) -> 0.5 | AD19: =+AB19/AC19 -> 436404.69
L20: Damper Assembly | M20: 0 | O20: D00006 | P20: =+M20 -> 0 | Q20: =+I19*P20 -> 0 | S20: =+Q20*40*52 -> 0 | T20: =+S20*0.0833 -> 0 | U20: =+T20 -> 0 | V20: =+S20*0.01 -> 0 | W20: =+S20*0.075 -> 0 | X20: =+S20*0.0018 -> 0 | Y20: =0.71*52*P20 -> 0 | Z20: =172*12*P20 -> 0 | AA20: =+(S20+T20+U20)*0.01 -> 0 | AB20: =SUM(S20:AA20) -> 0 | AC20: =IF(+J20>0,J20,AC19) -> 0.5 | AD20: =+AB20/AC20 -> 0
A22: W0000083 | B22: Riyaaz | C22: Davids | E22: M | F22: C | G22: Welder/Damper Assembler | H22: DAMPER | I22: 72.85 | J22: 0.5 | K22: OTT | L22: Cutting | M22: 0.45 | O22: D00001 | P22: =+M22 -> 0.45 | Q22: =+$I$22*P22 -> 32.7825 | S22: =+Q22*40*52 -> 68187.6 | T22: =+S22*0.0833 -> 5680.0271 | U22: =+T22 -> 5680.0271 | V22: =+S22*0.01 -> 681.876 | W22: =+S22*0.083 -> 5659.5708 | X22: =+S22*0.0018 -> 122.73768 | Y22: =0.71*52*P22 -> 16.614 | Z22: =172*12*P22 -> 928.8 | AA22: =+(S22+T22+U22)*0.01 -> 795.47654 | AB22: =SUM(S22:AA22) -> 87752.729 | AC22: =IF(+J22>0,J22,AC20) -> 0.5 | AD22: =+AB22/AC22 -> 175505.46
L23: Damper Assembly | M23: 0.45 | O23: D00006 | P23: =+M23 -> 0.45 | Q23: =+$I$22*P23 -> 32.7825 | S23: =+Q23*40*52 -> 68187.6 | T23: =+S23*0.0833 -> 5680.0271 | U23: =+T23 -> 5680.0271 | V23: =+S23*0.01 -> 681.876 | W23: =+S23*0.083 -> 5659.5708 | X23: =+S23*0.0018 -> 122.73768 | Y23: =0.71*52*P23 -> 16.614 | Z23: =172*12*P23 -> 928.8 | AA23: =+(S23+T23+U23)*0.01 -> 795.47654 | AB23: =SUM(S23:AA23) -> 87752.729 | AC23: =IF(+J23>0,J23,AC20) -> 0.5 | AD23: =+AB23/AC23 -> 175505.46
L24: Notching | M24: 0.1 | O24: D00003 | P24: =+M24 -> 0.1 | Q24: =+$I$22*P24 -> 7.285 | S24: =+Q24*40*52 -> 15152.8 | T24: =+S24*0.0833 -> 1262.2282 | U24: =+T24 -> 1262.2282 | V24: =+S24*0.01 -> 151.528 | W24: =+S24*0.083 -> 1257.6824 | X24: =+S24*0.0018 -> 27.27504 | Y24: =0.71*52*P24 -> 3.692 | Z24: =172*12*P24 -> 206.4 | AA24: =+(S24+T24+U24)*0.01 -> 176.77256 | AB24: =SUM(S24:AA24) -> 19500.606 | AC24: =IF(+J24>0,J24,AC22) -> 0.5 | AD24: =+AB24/AC24 -> 39001.213
A26: W0000084 | B26: John | C26: Overmeyer | E26: M | F26: C | G26: Welder/Damper Assembler | H26: DAMPER | I26: 72.85 | J26: 0.5 | K26: OTT | L26: Cutting | M26: 0.45 | O26: D00001 | P26: =+M26 -> 0.45 | Q26: =+$I$26*P26 -> 32.7825 | S26: =+Q26*40*52 -> 68187.6 | T26: =+S26*0.0833 -> 5680.0271 | U26: =+T26 -> 5680.0271 | V26: =+S26*0.01 -> 681.876 | W26: =+S26*0.083 -> 5659.5708 | X26: =+S26*0.0018 -> 122.73768 | Y26: =0.71*52*P26 -> 16.614 | Z26: =172*12*P26 -> 928.8 | AA26: =+(S26+T26+U26)*0.01 -> 795.47654 | AB26: =SUM(S26:AA26) -> 87752.729 | AC26: =IF(+J26>0,J26,AC23) -> 0.5 | AD26: =+AB26/AC26 -> 175505.46
L27: Damper Assembly | M27: 0.45 | O27: D00006 | P27: =+M27 -> 0.45 | Q27: =+$I$26*P27 -> 32.7825 | S27: =+Q27*40*52 -> 68187.6 | T27: =+S27*0.0833 -> 5680.0271 | U27: =+T27 -> 5680.0271 | V27: =+S27*0.01 -> 681.876 | W27: =+S27*0.083 -> 5659.5708 | X27: =+S27*0.0018 -> 122.73768 | Y27: =0.71*52*P27 -> 16.614 | Z27: =172*12*P27 -> 928.8 | AA27: =+(S27+T27+U27)*0.01 -> 795.47654 | AB27: =SUM(S27:AA27) -> 87752.729 | AC27: =IF(+J27>0,J27,AC23) -> 0.5 | AD27: =+AB27/AC27 -> 175505.46
L28: Notching | M28: 0.1 | O28: D00003 | P28: =+M28 -> 0.1 | Q28: =+$I$26*P28 -> 7.285 | S28: =+Q28*40*52 -> 15152.8 | T28: =+S28*0.0833 -> 1262.2282 | U28: =+T28 -> 1262.2282 | V28: =+S28*0.01 -> 151.528 | W28: =+S28*0.083 -> 1257.6824 | X28: =+S28*0.0018 -> 27.27504 | Y28: =0.71*52*P28 -> 3.692 | Z28: =172*12*P28 -> 206.4 | AA28: =+(S28+T28+U28)*0.01 -> 176.77256 | AB28: =SUM(S28:AA28) -> 19500.606 | AC28: =IF(+J28>0,J28,AC26) -> 0.5 | AD28: =+AB28/AC28 -> 39001.213
A30: W0000065 | B30: Neil | C30: Lamb | E30: M | F30: c | G30: General Worker | H30: DAMPER | I30: 87.84 | J30: 0.5 | K30: OTT | L30: Cutting | M30: 0.15 | O30: D00001 | P30: =+M30 -> 0.15 | Q30: =+$I$30*P30 -> 13.176 | S30: =+Q30*40*52 -> 27406.08 | T30: =+S30*0.0833 -> 2282.9265 | U30: =+T30 -> 2282.9265 | V30: =+S30*0.01 -> 274.0608 | W30: =+S30*0.083 -> 2274.7046 | X30: =+S30*0.0018 -> 49.330944 | Y30: =0.71*52*P30 -> 5.538 | Z30: =172*12*P30 -> 309.6 | AA30: =+(S30+T30+U30)*0.01 -> 319.71933 | AB30: =SUM(S30:AA30) -> 35204.887 | AC30: =IF(+J30>0,J30,AC20) -> 0.5 | AD30: =+AB30/AC30 -> 70409.773
L31: Notching | M31: 0.15 | O31: D00003 | P31: =+M31 -> 0.15 | Q31: =+$I$30*P31 -> 13.176 | S31: =+Q31*40*52 -> 27406.08 | T31: =+S31*0.0833 -> 2282.9265 | U31: =+T31 -> 2282.9265 | V31: =+S31*0.01 -> 274.0608 | W31: =+S31*0.083 -> 2274.7046 | X31: =+S31*0.0018 -> 49.330944 | Y31: =0.71*52*P31 -> 5.538 | Z31: =172*12*P31 -> 309.6 | AA31: =+(S31+T31+U31)*0.01 -> 319.71933 | AB31: =SUM(S31:AA31) -> 35204.887 | AC31: =IF(+J31>0,J31,AC30) -> 0.5 | AD31: =+AB31/AC31 -> 70409.773
K32: OTT | L32: Cutting | M32: 0.7 | O32: D00001 | P32: =+M32 -> 0.7 | Q32: =+$I$30*P32 -> 61.488 | S32: =+Q32*40*52 -> 127895.04 | T32: =+S32*0.0833 -> 10653.657 | U32: =+T32 -> 10653.657 | V32: =+S32*0.01 -> 1278.9504 | W32: =+S32*0.083 -> 10615.288 | X32: =+S32*0.0018 -> 230.21107 | Y32: =0.71*52*P32 -> 25.844 | Z32: =172*12*P32 -> 1444.8 | AA32: =+(S32+T32+U32)*0.01 -> 1492.0235 | AB32: =SUM(S32:AA32) -> 164289.47 | AC32: =IF(+J32>0,J32,AC31) -> 0.5 | AD32: =+AB32/AC32 -> 328578.94
A34: OTHER001 | B34: Other | E34: M | F34: C | G34: General Worker | H34: DAMPER | I34: 72.85 | J34: 0.5 | K34: OTT | L34: Brushing | M34: 0.1 | O34: D00002 | P34: =+M34 -> 0.1 | Q34: =+$I$34*P34 -> 7.285 | S34: =+Q34*40*52 -> 15152.8 | T34: =+S34*0.0833 -> 1262.2282 | U34: =+T34 -> 1262.2282 | V34: =+S34*0.01 -> 151.528 | W34: =+S34*0.083 -> 1257.6824 | X34: =+S34*0.0018 -> 27.27504 | Y34: =0.71*52*P34 -> 3.692 | Z34: =172*12*P34 -> 206.4 | AA34: =+(S34+T34+U34)*0.01 -> 176.77256 | AB34: =SUM(S34:AA34) -> 19500.606 | AC34: =IF(+J34>0,J34,AC6) -> 0.5 | AD34: =+AB34/AC34 -> 39001.213
K35: OTT | L35: Notching | M35: 0.1 | O35: D00003 | P35: =+M35 -> 0.1 | Q35: =+$I$34*P35 -> 7.285 | S35: =+Q35*40*52 -> 15152.8 | T35: =+S35*0.0833 -> 1262.2282 | U35: =+T35 -> 1262.2282 | V35: =+S35*0.01 -> 151.528 | W35: =+S35*0.083 -> 1257.6824 | X35: =+S35*0.0018 -> 27.27504 | Y35: =0.71*52*P35 -> 3.692 | Z35: =172*12*P35 -> 206.4 | AA35: =+(S35+T35+U35)*0.01 -> 176.77256 | AB35: =SUM(S35:AA35) -> 19500.606 | AC35: =IF(+J35>0,J35,AC31) -> 0.5 | AD35: =+AB35/AC35 -> 39001.213
K36: OTT | L36: Grille Assembly | M36: 0.4 | O36: D00005 | P36: =+M36 -> 0.4 | Q36: =+$I$34*P36 -> 29.14 | S36: =+Q36*40*52 -> 60611.2 | T36: =+S36*0.0833 -> 5048.913 | U36: =+T36 -> 5048.913 | V36: =+S36*0.01 -> 606.112 | W36: =+S36*0.083 -> 5030.7296 | X36: =+S36*0.0018 -> 109.10016 | Y36: =0.71*52*P36 -> 14.768 | Z36: =172*12*P36 -> 825.6 | AA36: =+(S36+T36+U36)*0.01 -> 707.09026 | AB36: =SUM(S36:AA36) -> 78002.426 | AC36: =IF(+J36>0,J36,AC31) -> 0.5 | AD36: =+AB36/AC36 -> 156004.85
K37: OTT | L37: Damper Assembly | M37: 0.4 | O37: D00006 | P37: =+M37 -> 0.4 | Q37: =+$I$34*P37 -> 29.14 | S37: =+Q37*40*52 -> 60611.2 | T37: =+S37*0.0833 -> 5048.913 | U37: =+T37 -> 5048.913 | V37: =+S37*0.01 -> 606.112 | W37: =+S37*0.083 -> 5030.7296 | X37: =+S37*0.0018 -> 109.10016 | Y37: =0.71*52*P37 -> 14.768 | Z37: =172*12*P37 -> 825.6 | AA37: =+(S37+T37+U37)*0.01 -> 707.09026 | AB37: =SUM(S37:AA37) -> 78002.426 | AC37: =IF(+J37>0,J37,AC32) -> 0.5 | AD37: =+AB37/AC37 -> 156004.85
A39: Despatch
A40: CON049 | B40: Sean | C40: Ontong | E40: M | F40: C | G40: Supervisor | H40: DESPATCH | I40: 111.14 | J40: 0.75 | K40: LANS | L40: Despatch | M40: 1 | O40: F00001 | P40: =+M40 -> 1 | Q40: =+I40*P40 -> 111.14 | S40: =+Q40*40*52 -> 231171.2 | T40: =+S40*0.0833 -> 19256.561 | U40: =+T40 -> 19256.561 | V40: =+S40*0.01 -> 2311.712 | W40: =+S40*0.083 -> 19187.21 | X40: =+S40*0.0018 -> 416.10816 | Y40: =0.71*52*P40 -> 36.92 | Z40: =172*12*P40 -> 2064 | AA40: =+(S40+T40+U40)*0.01 -> 2696.8432 | AB40: =SUM(S40:AA40) -> 296397.11 | AC40: =IF(+J40>0,J40,AC35) -> 0.75 | AD40: =+AB40/AC40 -> 395196.15
A41: SWL004 | B41: Ebriham | C41: Fredericks | E41: M | F41: C | G41: Picker/Packer | H41: DESPATCH | I41: 76.04 | J41: 0.5 | K41: LANS | L41: Despatch | M41: 1 | O41: F00001 | P41: =+M41 -> 1 | Q41: =+I41*P41 -> 76.04 | S41: =+Q41*40*52 -> 158163.2 | T41: =+S41*0.0833 -> 13174.995 | U41: =+T41 -> 13174.995 | V41: =+S41*0.01 -> 1581.632 | W41: =+S41*0.083 -> 13127.546 | X41: =+S41*0.0018 -> 284.69376 | Y41: =0.71*52*P41 -> 36.92 | Z41: =172*12*P41 -> 2064 | AA41: =+(S41+T41+U41)*0.01 -> 1845.1319 | AB41: =SUM(S41:AA41) -> 203453.11 | AC41: =IF(+J41>0,J41,AC39) -> 0.5 | AD41: =+AB41/AC41 -> 406906.22
A42: W0000017 | B42: Brandon | C42: Jaftha | E42: M | F42: C | G42: Leading Hand/De | H42: DESPATCH | I42: 81.61 | J42: 0.5 | K42: LANS | L42: Despatch | M42: 1 | O42: F00001 | P42: =+M42 -> 1 | Q42: =+I42*P42 -> 81.61 | S42: =+Q42*40*52 -> 169748.8 | T42: =+S42*0.0833 -> 14140.075 | U42: =+T42 -> 14140.075 | V42: =+S42*0.01 -> 1697.488 | W42: =+S42*0.083 -> 14089.15 | X42: =+S42*0.0018 -> 305.54784 | Y42: =0.71*52*P42 -> 36.92 | Z42: =172*12*P42 -> 2064 | AA42: =+(S42+T42+U42)*0.01 -> 1980.2895 | AB42: =SUM(S42:AA42) -> 218202.35 | AC42: =IF(+J42>0,J42,AC41) -> 0.5 | AD42: =+AB42/AC42 -> 436404.69
A43: W0000074 | B43: Van Wyk DLM | E43: M | F43: C | H43: DESPATCH | I43: 66.93 | J43: 0.5 | K43: LANS | L43: Despatch | M43: 1 | O43: F00001 | P43: =+M43 -> 1 | Q43: =+I43*P43 -> 66.93 | S43: =+Q43*40*52 -> 139214.4 | T43: =+S43*0.0833 -> 11596.56 | U43: =+T43 -> 11596.56 | V43: =+S43*0.01 -> 1392.144 | W43: =+S43*0.083 -> 11554.795 | X43: =+S43*0.0018 -> 250.58592 | Y43: =0.71*52*P43 -> 36.92 | Z43: =172*12*P43 -> 2064 | AA43: =+(S43+T43+U43)*0.01 -> 1624.0752 | AB43: =SUM(S43:AA43) -> 179330.04 | AC43: =IF(+J43>0,J43,#REF!) -> 0.5 | AD43: =+AB43/AC43 -> 358660.08
A44: W0000044 | B44: Bernard | C44: Manel | E44: M | F44: C | G44: Delivery Driver | H44: DESPATCH | I44: 81.61 | J44: 0.5 | K44: LANS | L44: Despatch | M44: 1 | O44: F00001 | P44: =+M44 -> 1 | Q44: =+I44*P44 -> 81.61 | S44: =+Q44*40*52 -> 169748.8 | T44: =+S44*0.0833 -> 14140.075 | U44: =+T44 -> 14140.075 | V44: =+S44*0.01 -> 1697.488 | W44: =+S44*0.083 -> 14089.15 | X44: =+S44*0.0018 -> 305.54784 | Y44: =0.71*52*P44 -> 36.92 | Z44: =172*12*P44 -> 2064 | AA44: =+(S44+T44+U44)*0.01 -> 1980.2895 | AB44: =SUM(S44:AA44) -> 218202.35 | AC44: =IF(+J44>0,J44,AC43) -> 0.5 | AD44: =+AB44/AC44 -> 436404.69
A45: W0000052 | B45: Phanuel | C45: Tlou | E45: M | F45: A | G45: Delivery Driver | H45: DESPATCH | I45: 81.61 | J45: 0.5 | K45: LANS | L45: Despatch | M45: 1 | O45: F00001 | P45: =+M45 -> 1 | Q45: =+I45*P45 -> 81.61 | S45: =+Q45*40*52 -> 169748.8 | T45: =+S45*0.0833 -> 14140.075 | U45: =+T45 -> 14140.075 | V45: =+S45*0.01 -> 1697.488 | W45: =+S45*0.083 -> 14089.15 | X45: =+S45*0.0018 -> 305.54784 | Y45: =0.71*52*P45 -> 36.92 | Z45: =172*12*P45 -> 2064 | AA45: =+(S45+T45+U45)*0.01 -> 1980.2895 | AB45: =SUM(S45:AA45) -> 218202.35 | AC45: =IF(+J45>0,J45,AC44) -> 0.5 | AD45: =+AB45/AC45 -> 436404.69
A46: W0000064 | B46: Mpendulo | C46: Yekele | E46: M | F46: A | G46: Driver- Code 10 | H46: DESPATCH | I46: 81.61 | J46: 0.5 | K46: LANS | L46: Despatch | M46: 1 | O46: F00001 | P46: =+M46 -> 1 | Q46: =+I46*P46 -> 81.61 | S46: =+Q46*40*52 -> 169748.8 | T46: =+S46*0.0833 -> 14140.075 | U46: =+T46 -> 14140.075 | V46: =+S46*0.01 -> 1697.488 | W46: =+S46*0.083 -> 14089.15 | X46: =+S46*0.0018 -> 305.54784 | Y46: =0.71*52*P46 -> 36.92 | Z46: =172*12*P46 -> 2064 | AA46: =+(S46+T46+U46)*0.01 -> 1980.2895 | AB46: =SUM(S46:AA46) -> 218202.35 | AC46: =IF(+J46>0,J46,AC45) -> 0.5 | AD46: =+AB46/AC46 -> 436404.69
A47: W0000005 | B47: Omar | C47: Karriem | E47: M | F47: A | G47: Driver- Code 10 | H47: DESPATCH | I47: 75.43 | J47: 0.5 | K47: LANS | L47: Despatch | M47: 1 | O47: F00001 | P47: =+M47 -> 1 | Q47: =+I47*P47 -> 75.43 | S47: =+Q47*40*52 -> 156894.4 | T47: =+S47*0.0833 -> 13069.304 | U47: =+T47 -> 13069.304 | V47: =+S47*0.01 -> 1568.944 | W47: =+S47*0.083 -> 13022.235 | X47: =+S47*0.0018 -> 282.40992 | Y47: =0.71*52*P47 -> 36.92 | Z47: =172*12*P47 -> 2064 | AA47: =+(S47+T47+U47)*0.01 -> 1830.3301 | AB47: =SUM(S47:AA47) -> 201837.85 | AC47: =IF(+J47>0,J47,AC46) -> 0.5 | AD47: =+AB47/AC47 -> 403675.69
A50: PREPARATION
A51: CON285 | B51: Nkosiyethu | C51: Skeyi | E51: M | F51: A | G51: Electric Prep Assembler | H51: PREPARATION | I51: 78.33 | J51: 0.75 | K51: LANS | L51: Preparations | M51: 1 | O51: R00001 | P51: =+M51 -> 1 | Q51: =+P51*I51 -> 78.33 | S51: =+Q51*40*52 -> 162926.4 | T51: =+S51*0.0833 -> 13571.769 | U51: =+T51 -> 13571.769 | V51: =+S51*0.01 -> 1629.264 | W51: =+S51*0.083 -> 13522.891 | X51: =+S51*0.0018 -> 293.26752 | Y51: =0.71*52*P51 -> 36.92 | Z51: =172*12*P51 -> 2064 | AA51: =+(S51+T51+U51)*0.01 -> 1900.6994 | AB51: =SUM(S51:AA51) -> 209516.98 | AC51: =IF(+J51>0,J51,AC50) -> 0.75 | AD51: =+AB51/AC51 -> 279355.97
A52: CON377B | B52: Shaheed | C52: Dreyer | E52: M | F52: C | G52: Electrical Prep Assembler | H52: PREPARATION | I52: 78.33 | J52: 0.5 | K52: LANS | L52: Induction Channel Assembly | M52: 1 | O52: A00001 | P52: =+M52 -> 1 | Q52: =+P52*I52 -> 78.33 | S52: =+Q52*40*52 -> 162926.4 | T52: =+S52*0.0833 -> 13571.769 | U52: =+T52 -> 13571.769 | V52: =+S52*0.01 -> 1629.264 | W52: =+S52*0.083 -> 13522.891 | X52: =+S52*0.0018 -> 293.26752 | Y52: =0.71*52*P52 -> 36.92 | Z52: =172*12*P52 -> 2064 | AA52: =+(S52+T52+U52)*0.01 -> 1900.6994 | AB52: =SUM(S52:AA52) -> 209516.98 | AC52: =IF(+J52>0,J52,AC51) -> 0.5 | AD52: =+AB52/AC52 -> 419033.96
...

Sheet Overhead
